Workbook

Sheet Март 26
A1: 3 | B1: Вчера | C1: =DAY(TODAY()-1) -> 26 | F1: Дней в месяце | G1: 31
A2: Актуально на | B2: 46083 | M2: Оз | O2: Вб | Q2: Ям | S2: Лету | U2: ЗЯ | W2: Магнит Маркет | Y2: Сайт | AE2: план | AF2: ауты | AG2: реальный план | AI2: выручка | AJ2: отказы/возвраты | AK2: раздачи | AL2: выкупы | AM2: реальная выручка
B3: Ozon | M3: Биг–Л | N3: Смарт | O3: Биг–Л | P3: Смарт | Q3: Биг–Л | R3: Смарт | S3: Биг–Л | T3: Смарт | U3: Биг–Л | V3: Смарт | W3: Биг–Л | X3: Смарт | Y3: qeep | Z3: harly | AA3: Алтея | AC3: WB | AD3: Биг–Л | AE3: =D39 -> 2.0608031e+08 | AG3: =AE3-AF3 -> 2.0608031e+08 | AI3: =O35 -> 290489634 | AM3: =AI3-SUM(AJ3:AL3) -> 290489634
B4: Биг–Л / Март | до | D4: =TODAY()-1 -> 46107 | F4: Смарт/ Март| до | H4: =$D$4 -> 46107 | K4: 46082 | L4: =SUM(M4:AA4) -> 20051499 | M4: 2945127 | N4: 3391718 | O4: 9196294 | P4: 4172079 | Q4: 134607 | R4: 81004 | S4: 16982 | T4: 43929 | U4: 2160 | V4: 62928 | W4: 2150.16 | X4: 2520.99 | AD4: Смарт–Сэйл | AE4: =H39 -> 1.1437699e+08 | AG4: =AE4-AF4 -> 1.1437699e+08 | AI4: =P35 -> 118684688 | AM4: =AI4-SUM(AJ4:AL4) -> 118684688
A5: =IFERROR(C5/$C$15, " ") -> 0.90385015 | B5: Оплата за клик | C5: 7249209 | F5: Оплата за клик | G5: 8738826 | I5: =IFERROR(G5/$G$15, " ") -> 0.92420892 | K5: 46083 | L5: =SUM(M5:AA5) -> 19578836 | M5: 3007289 | N5: 3171863 | O5: 8671856 | P5: 4350042 | Q5: 179463 | R5: 86947 | S5: 13327 | T5: 35981 | U5: 720 | V5: 53664 | W5: 3155.5 | X5: 4528 | AC5: Ozon | AD5: Биг–Л | AE5: =D21 -> 105053826 | AG5: =AE5-AF5 -> 105053826 | AI5: =M35 -> 90218782 | AM5: =AI5-SUM(AJ5:AL5) -> 90218782
A6: =IFERROR(C6/$C$15, " ") -> 0.0031626986 | B6: Оплата за заказ | C6: 25366 | F6: Оплата за заказ | G6: 259877 | I6: =IFERROR(G6/$G$15, " ") -> 0.027484314 | K6: 46084 | L6: =SUM(M6:AA6) -> 19591015 | M6: 3568197 | N6: 3044559 | O6: 8488956 | P6: 4112286 | Q6: 163215 | R6: 80224 | S6: 12112 | T6: 52186 | U6: 0 | V6: 62968 | W6: 2884 | X6: 3428 | AD6: Смарт–Сэйл | AE6: =H21 -> 84254055 | AG6: =AE6-AF6 -> 84254055 | AI6: =N35 -> 71210163 | AM6: =AI6-SUM(AJ6:AL6) -> 71210163
A7: =IFERROR(C7/$C$15, " ") -> 0.076261607 | B7: Медийка | C7: 611646 | F7: Медийка | G7: 334224 | I7: =IFERROR(G7/$G$15, " ") -> 0.035347174 | K7: 46085 | L7: =SUM(M7:AA7) -> 18415458 | M7: 2896596 | N7: 2872328 | O7: 8033493 | P7: 4331084 | Q7: 102960 | R7: 58136 | S7: 11886 | T7: 39485 | U7: 1710 | V7: 63302 | W7: 1464.13 | X7: 3014 | AC7: ЯМаркет | AD7: Биг–Л | AE7: =D78 -> 3069853 | AG7: =AE7-AF7 -> 3069853 | AI7: =Q35 -> 4382190 | AM7: =AI7-SUM(AJ7:AL7) -> 4382190
A8: =IFERROR(C8/$C$15, " ") -> 0.00023727097 | B8: Баллы за отзывы | C8: 1903 | F8: Баллы за отзывы | I8: =IFERROR(G8/$G$15, " ") -> 0 | K8: 46086 | L8: =SUM(M8:AA8) -> 18359103 | M8: 3080360 | N8: 2861536 | O8: 7770325 | P8: 4271487 | Q8: 105469 | R8: 90888 | S8: 21717 | T8: 57184 | U8: 5123 | V8: 89257 | W8: 1502.43 | X8: 4255 | AD8: Смарт–Сэйл | AE8: =H78 -> 2257611 | AG8: =AE8-AF8 -> 2257611 | AI8: =R35 -> 1494137 | AM8: =AI8-SUM(AJ8:AL8) -> 1494137
A9: =IFERROR(C9/$C$15, " ") -> 0.01633903 | B9: Бонусы продавца | C9: 131045 | F9: Бонусы продавца | G9: 122539 | I9: =IFERROR(G9/$G$15, " ") -> 0.012959594 | K9: 46087 | L9: =SUM(M9:AA9) -> 17470815 | M9: 2960566 | N9: 2942818 | O9: 7054264 | P9: 3913988 | Q9: 299320 | R9: 58859 | S9: 27911 | T9: 76444 | U9: 9856 | V9: 119808 | W9: 1011.13 | X9: 5970 | AC9: Летуаль | AD9: Биг–Л | AE9: =S42 -> 619304 | AG9: =AE9-AF9 -> 619304 | AI9: =S35 -> 490176 | AM9: =AI9-SUM(AJ9:AL9) -> 490176
A10: =IFERROR(C10/$C$15, " ") -> 0 | B10: Рассылки | C10: 0 | F10: Рассылки | I10: =IFERROR(G10/$G$15, " ") -> 0 | K10: 46088 | L10: =SUM(M10:AA10) -> 18122854 | M10: 2966816 | N10: 2690818 | O10: 8071469 | P10: 3932225 | Q10: 101684 | R10: 61858 | S10: 24663 | T10: 90823 | U10: 18190 | V10: 158017 | W10: 1020 | X10: 5270.7 | AD10: Смарт–Сэйл | AE10: =T42 -> 1719666 | AG10: =AE10-AF10 -> 1719666 | AI10: =T35 -> 1274528 | AM10: =AI10-SUM(AJ10:AL10) -> 1274528
A11: =IFERROR(C11/$C$15, " ") -> 0 | B11: Закрепление отзыва | C11: 0 | F11: Закрепление отзыва | I11: =IFERROR(G11/$G$15, " ") -> 0 | K11: 46089 | L11: =SUM(M11:AA11) -> 17009761 | M11: 2571667 | N11: 2299783 | O11: 7749386 | P11: 3943225 | Q11: 105112 | R11: 41541 | S11: 38052 | T11: 107299 | U11: 14371 | V11: 136238 | W11: 421.28 | X11: 2666 | AC11: Золотое Яблоко | AD11: Биг–Л | AE11: =U42 -> 141359 | AG11: =AE11-AF11 -> 141359 | AI11: =U35 -> 100903 | AM11: =AI11-SUM(AJ11:AL11) -> 100903
B12: Иные электронные услуги | C12: 0 | F12: Иные электронные услуги | I12: =IFERROR(G12/$G$15, " ") -> 0 | K12: 46090 | L12: =SUM(M12:AA12) -> 24043922 | M12: 3764474 | N12: 2900168 | O12: 11849879 | P12: 4998959 | Q12: 144166 | R12: 41253 | S12: 43214 | T12: 133590 | U12: 8039 | V12: 148975 | W12: 4705.42 | X12: 6500.08 | AD12: Смарт–Сэйл | AE12: =V42 -> 1599107 | AG12: =AE12-AF12 -> 1599107 | AI12: =V35 -> 2120688 | AM12: =AI12-SUM(AJ12:AL12) -> 2120688
B13: Продвижение бренда | C13: 0 | F13: Продвижение бренда | I13: =IFERROR(G13/$G$15, " ") -> 0 | K13: 46091 | L13: =SUM(M13:AA13) -> 23853038 | M13: 3911352 | N13: 2863966 | O13: 11628689 | P13: 4953182 | Q13: 142061 | R13: 61566 | S13: 33783 | T13: 104680 | U13: 8158 | V13: 145133 | W13: 0 | X13: 467.5 | AD13: итог | AE13: =SUM(AE3:AE12) -> 5.1917208e+08 | AF13: =SUM(AF3:AF12) -> 0 | AG13: =SUM(AG3:AG12) -> 5.1917208e+08 | AI13: =SUM(AI3:AI12) -> 5.8046589e+08 | AJ13: =SUM(AJ3:AJ12) -> 0 | AK13: =SUM(AK3:AK12) -> 0 | AL13: =SUM(AL3:AL12) -> 0 | AM13: =SUM(AM3:AM12) -> 5.8046589e+08
B14: Ozon Рассрочка | C14: 1197 | F14: Ozon Рассрочка | K14: 46092 | L14: =SUM(M14:AA14) -> 22236976 | M14: 3872679 | N14: 2875709 | O14: 10344154 | P14: 4733883 | Q14: 180466 | R14: 60308 | S14: 20470 | T14: 49268 | U14: 2759 | V14: 85661 | W14: 3840.16 | X14: 7778.84
B15: Итого расходов | C15: =SUM(C5:C14) -> 8020366 | F15: Итого расходов | G15: =SUM(G5:G14) -> 9455466 | H15: =SUM(H5:H14) -> 0 | K15: 46093 | L15: =SUM(M15:AA15) -> 20520671 | M15: 3859705 | N15: 3092489 | O15: 8833371 | P15: 4394002 | Q15: 140487 | R15: 58106 | S15: 14501 | T15: 45955 | U15: 3801 | V15: 74085 | W15: 0 | X15: 4168.6
B16: Выручка | D16: =M35 -> 90218782 | F16: Выручка | H16: =N35 -> 71210163 | K16: 46094 | L16: =SUM(M16:AA16) -> 19577117 | M16: 3509459 | N16: 2865973.6 | O16: 8740909 | P16: 4134370 | Q16: 114001 | R16: 62938 | S16: 15814 | T16: 55687 | U16: 4259 | V16: 64011 | W16: 6163.92 | X16: 3531.24
B17: ДРР / Факт | D17: =C15/D16 -> 0.088899072 | F17: ДРР / Факт | H17: =G15/H16 -> 0.13278254 | K17: 46095 | L17: =SUM(M17:AA17) -> 21112873 | M17: 3452216 | N17: 3044362 | O17: 9524177 | P17: 4687344 | Q17: 195086 | R17: 45308 | S17: 19788 | T17: 53394 | U17: 3413 | V17: 80937 | W17: 2090.4 | X17: 4757.49 | AE17: Без вычетов | AI17: С вычетом всего
A18: =D17/C18 -> 0.59266048 | B18: ДРР / План | C18: 0.15 | D18: =D16*C18 -> 13532817 | F18: ДРР / План | G18: 0.13 | H18: =H16*G18 -> 9257321.2 | I18: =H17/G18 -> 1.0214041 | K18: 46096 | L18: =SUM(M18:AA18) -> 22925434 | M18: 3654183 | N18: 3106266.1 | O18: 10917100 | P18: 4802264 | Q18: 211721 | R18: 52353 | S18: 16462 | T18: 58043 | U18: 6825 | V18: 92768 | W18: 2476.52 | X18: 4972.18 | AE18: план | AF18: выручка | AG18: дельта | AI18: реальный план | AJ18: реальная выручка | AK18: дельта
B19: Перерасход в деньгах | D19: =C15-D18 -> -5512451.3 | F19: Перераход в деньгах | H19: =G15-H18 -> 198144.77 | K19: 46097 | L19: =SUM(M19:AA19) -> 20543142 | M19: 3241939 | N19: 2833187 | O19: 9344888 | P19: 4786615 | Q19: 152313 | R19: 55254 | S19: 20448 | T19: 30366 | U19: 2201 | V19: 72032 | W19: 0 | X19: 3898.89 | AC19: WB | AD19: Биг–Л | AE19: =AE3 -> 2.0608031e+08 | AF19: =AI3 -> 290489634 | AG19: =IFERROR(AF19/AE19, " ") -> 1.4095943 | AI19: =AG3 -> 2.0608031e+08 | AJ19: =AM3 -> 290489634 | AK19: =IFERROR(AJ19/AI19, " ") -> 1.4095943
K20: 46098 | L20: =SUM(M20:AA20) -> 21487958 | M20: 3023131 | N20: 2638046.5 | O20: 10218979 | P20: 5288172 | Q20: 167861 | R20: 40414 | S20: 12716 | T20: 18561 | U20: 406 | V20: 73937 | W20: 3353.51 | X20: 2381.2 | AD20: Смарт–Сэйл | AE20: =AE4 -> 1.1437699e+08 | AF20: =AI4 -> 118684688 | AG20: =IFERROR(AF20/AE20, " ") -> 1.0376623 | AI20: =AG4 -> 1.1437699e+08 | AJ20: =AM4 -> 118684688 | AK20: =IFERROR(AJ20/AI20, " ") -> 1.0376623
B21: План | D21: =M42 -> 105053826 | F21: План | H21: =N42 -> 84254055 | K21: 46099 | L21: =SUM(M21:AA21) -> 25002721 | M21: 4246087 | N21: 3407136.1 | O21: 12051770 | P21: 4943058 | Q21: 166674 | R21: 63061 | S21: 14012 | T21: 28323 | U21: 2255 | V21: 74396 | W21: 0 | X21: 5949.15 | AC21: Ozon | AD21: Биг–Л | AE21: =AE5 -> 105053826 | AF21: =AI5 -> 90218782 | AG21: =IFERROR(AF21/AE21, " ") -> 0.85878626 | AI21: =AG5 -> 105053826 | AJ21: =AM5 -> 90218782 | AK21: =IFERROR(AJ21/AI21, " ") -> 0.85878626
B22: Плато продаж | D22: =D16/$C$1 -> 3469953.2 | F22: Плато продаж | H22: =H16/$C$1 -> 2738852.4 | K22: 46100 | L22: =SUM(M22:AA22) -> 25508707 | M22: 3132743 | N22: 2281600 | O22: 15170599 | P22: 4537065 | Q22: 221414 | R22: 69428 | S22: 9416 | T22: 17682 | U22: 0 | V22: 64132 | W22: 1452.36 | X22: 3175.85 | AD22: Смарт–Сэйл | AE22: =AE6 -> 84254055 | AF22: =AI6 -> 71210163 | AG22: =IFERROR(AF22/AE22, " ") -> 0.84518381 | AI22: =AG6 -> 84254055 | AJ22: =AM6 -> 71210163 | AK22: =IFERROR(AJ22/AI22, " ") -> 0.84518381
B23: Нужно сделать на вчера | D23: =D21/$G$1*$C$1 -> 88109661 | F23: Нужно сделать на вчера | H23: =H21/$G$1*$C$1 -> 70664691 | K23: 46101 | L23: =SUM(M23:AA23) -> 22322077 | M23: 3027373 | N23: 2195710 | O23: 12387900 | P23: 4398525 | Q23: 147256 | R23: 66531 | S23: 13031 | T23: 20231 | U23: 540 | V23: 61974 | W23: 430.16 | X23: 2575.63 | AC23: ЯМаркет | AD23: Биг–Л | AE23: =AE7 -> 3069853 | AF23: =AI7 -> 4382190 | AG23: =IFERROR(AF23/AE23, " ") -> 1.4274918 | AI23: =AG7 -> 3069853 | AJ23: =AM7 -> 4382190 | AK23: =IFERROR(AJ23/AI23, " ") -> 1.4274918
B24: Нужно делать в день | D24: =(D21-D16)/($G$1-$C$1) -> 2967008.8 | F24: Нужно делать в день | H24: =(H21-H16)/($G$1-$C$1) -> 2608778.4 | K24: 46102 | L24: =SUM(M24:AA24) -> 26143611 | M24: 3522975 | N24: 2100022 | O24: 14680702 | P24: 5460096 | Q24: 232610 | R24: 50230 | S24: 10895 | T24: 28881 | U24: 0 | V24: 54798 | W24: 1472.35 | X24: 929.32 | AD24: Смарт–Сэйл | AE24: =AE8 -> 2257611 | AF24: =AI8 -> 1494137 | AG24: =IFERROR(AF24/AE24, " ") -> 0.66182217 | AI24: =AG8 -> 2257611 | AJ24: =AM8 -> 1494137 | AK24: =IFERROR(AJ24/AI24, " ") -> 0.66182217
B25: Дельта от плана | D25: =D16-D23 -> 2109121.5 | F25: Дельта от плана | H25: =H16-H23 -> 545471.84 | K25: 46103 | L25: =SUM(M25:AA25) -> 31068516 | M25: 3736853 | N25: 2627885 | O25: 17666377 | P25: 6631292 | Q25: 258740 | R25: 54402 | S25: 12918 | T25: 25542 | U25: 0 | V25: 54507 | W25: 0 | X25: 0 | AC25: Летуаль | AD25: Биг–Л | AE25: =AE9 -> 619304 | AF25: =AI9 -> 490176 | AG25: =IFERROR(AF25/AE25, " ") -> 0.79149497 | AI25: =AG9 -> 619304 | AJ25: =AM9 -> 490176 | AK25: =IFERROR(AJ25/AI25, " ") -> 0.79149497
B26: Прогноз по выручке | D26: =D16/$C$1*$G$1 -> 1.0756855e+08 | F26: Прогноз по выручке | H26: =H16/$C$1*$G$1 -> 84904425 | K26: 46104 | L26: =SUM(M26:AA26) -> 27972237 | M26: 3577557 | N26: 2219666 | O26: 16961692 | P26: 4833602 | Q26: 218223 | R26: 55500 | S26: 13293 | T26: 16275 | U26: 0 | V26: 66034 | W26: 4719.16 | X26: 5676.24 | AD26: Смарт–Сэйл | AE26: =AE10 -> 1719666 | AF26: =AI10 -> 1274528 | AG26: =IFERROR(AF26/AE26, " ") -> 0.74114857 | AI26: =AG10 -> 1719666 | AJ26: =AM10 -> 1274528 | AK26: =IFERROR(AJ26/AI26, " ") -> 0.74114857
B27: Прогноз по выручке (%) | D27: =D26/D21 -> 1.0239375 | F27: Прогноз по выручке (%) | H27: =H26/H21 -> 1.0077192 | K27: 46105 | L27: =SUM(M27:AA27) -> 26838275 | M27: 3737111 | N27: 2203706 | O27: 16411407 | P27: 4087386 | Q27: 238745 | R27: 47283 | S27: 13665 | T27: 31031 | U27: 0 | V27: 56167 | W27: 5302.95 | X27: 6471.06 | AC27: Золотое Яблоко | AD27: Биг–Л | AE27: =AE11 -> 141359 | AF27: =AI11 -> 100903 | AG27: =IFERROR(AF27/AE27, " ") -> 0.71380669 | AI27: =AG11 -> 141359 | AJ27: =AM11 -> 100903 | AK27: =IFERROR(AJ27/AI27, " ") -> 0.71380669
K28: 46106 | L28: =SUM(M28:AA28) -> 26147537 | M28: 4161394 | N28: 2565808 | O28: 14909070 | P28: 4095915 | Q28: 258536 | R28: 50745 | S28: 22289 | T28: 26028 | U28: 5558 | V28: 51721 | W28: 0 | X28: 473.45 | AD28: Смарт–Сэйл | AE28: =AE12 -> 1599107 | AF28: =AI12 -> 2120688 | AG28: =IFERROR(AF28/AE28, " ") -> 1.3261702 | AI28: =AG12 -> 1599107 | AJ28: =AM12 -> 2120688 | AK28: =IFERROR(AJ28/AI28, " ") -> 1.3261702
B29: Wildberries / Расход бонусы + рубли | K29: 46107 | L29: =SUM(M29:AA29) -> 24708477 | M29: 4790933 | N29: 2113040 | O29: 13811928 | P29: 3892542 | S29: 16811 | T29: 27660 | U29: 559 | V29: 53238 | W29: 0 | X29: 1765.74 | AE29: =SUM(AE19:AE28) -> 5.1917208e+08 | AF29: =SUM(AF19:AF28) -> 5.8046589e+08 | AG29: =IFERROR(AF29/AE29, " ") -> 1.1180607 | AI29: =SUM(AI19:AI24) -> 5.1509265e+08 | AJ29: =SUM(AJ19:AJ24) -> 5.7647959e+08 | AK29: =IFERROR(AJ29/AI29, " ") -> 1.1191765
B30: =B4 -> Биг–Л / Март | до | D30: =$D$4 -> 46107 | F30: =F4 -> Смарт/ Март| до | H30: =$D$4 -> 46107 | K30: 46108 | L30: =SUM(M30:AA30) -> 0
A31: =IFERROR(C31/$C$33, " ") -> 0.89593436 | B31: Затраты из РК | C31: 11596408 | F31: Затраты из РК | G31: 7142270 | I31: =IFERROR(G31/$G$33, " ") -> 0.95848558 | K31: 46109 | L31: =SUM(M31:AA31) -> 0 | AC31: Только рубли | AE31: реальная выручка | AF31: реклама | AG31: ДРР | AI31: ДРР план | AJ31: ДРР факт | AK31: дельта
A32: =IFERROR(C32/$C$33, " ") -> 0.10406564 | B32: Отзывы за баллы | C32: 1346959.9 | F32: Отзывы за баллы | G32: 309349.7 | I32: =IFERROR(G32/$G$33, " ") -> 0.041514424 | K32: 46110 | L32: =SUM(M32:AA32) -> 0 | AC32: WB | AD32: Биг–Л | AE32: =AM3 -> 290489634 | AF32: =C51 -> 0 | AG32: =AF32/AE32 -> 0 | AI32: =C36 -> 0.08 | AJ32: =AG32 -> 0 | AK32: =AJ32/AI32-1 -> -1
B33: Итого расходов | C33: =SUM(C31:C32) -> 12943368 | F33: Итого расходов | G33: =SUM(G31:G32) -> 7451619.7 | K33: 46111 | L33: =SUM(M33:AA33) -> 0 | AD33: Смарт–Сэйл | AE33: =AM4 -> 118684688 | AF33: =G51 -> 0 | AG33: =AF33/AE33 -> 0 | AI33: =G36 -> 0.08 | AJ33: =AG33 -> 0 | AK33: =AJ33/AI33-1 -> -1
B34: Выручка | D34: =O35 -> 290489634 | F34: Выручка | H34: =P35 -> 118684688 | K34: 46112 | L34: =SUM(M34:AA34) -> 0 | AC34: Ozon | AD34: Биг–Л | AE34: =AM5 -> 90218782 | AF34: =C15 -> 8020366 | AG34: =AF34/AE34 -> 0.088899072 | AI34: =C18 -> 0.15 | AJ34: =AG34 -> 0.088899072 | AK34: =AJ34/AI34-1 -> -0.40733952
B35: ДРР / Факт | D35: =C33/D34 -> 0.044557073 | F35: ДРР / Факт | H35: =G33/H34 -> 0.062785013 | K35: =L35/C1 -> 22331255 | L35: =SUM(L4:L34) -> 580612630 | M35: =SUM(M4:M34) -> 90218782 | N35: =SUM(N4:N34) -> 71210163 | O35: =SUM(O4:O34) -> 290489634 | P35: =SUM(P4:P34) -> 118684688 | Q35: =SUM(Q4:Q34) -> 4382190 | R35: =SUM(R4:R34) -> 1494137 | S35: =SUM(S4:S34) -> 490176 | ... AA35: =SUM(AA4:AA34) -> 0 | AD35: Смарт–Сэйл | AE35: =AM6 -> 71210163 | AF35: =G15 -> 9455466 | AG35: =AF35/AE35 -> 0.13278254 | AI35: =G18 -> 0.13 | AJ35: =AG35 -> 0.13278254 | AK35: =AJ35/AI35-1 -> 0.021404115
A36: =D35/C36 -> 0.55696342 | B36: ДРР / План | C36: 0.08 | D36: =D34*C36 -> 23239171 | F36: ДРР / План | G36: 0.08 | H36: =H34*G36 -> 9494775 | I36: =H35/G36 -> 0.78481266 | M36: =M35/$L$35 -> 0.1553855 | N36: =N35/$L$35 -> 0.1226466 | O36: =O35/$L$35 -> 0.50031573 | P36: =P35/$L$35 -> 0.20441286 | Q36: =Q35/$L$35 -> 0.0075475279 | R36: =R35/$L$35 -> 0.0025733801 | S36: =S35/$L$35 -> 0.0008442393 | T36: =T35/$L$35 -> 0.0021951434 | ... AA36: =AA35/$L$35 -> 0 | AC36: ЯМаркет | AD36: Биг–Л | AE36: =AM7 -> 4382190 | AF36: =C72 -> 530991 | AG36: =AF36/AE36 -> 0.12117024 | AI36: =C75 | AJ36: =AG36 -> 0.12117024 | AK36: =AJ36/AI36-1 -> #DIV/0!
B37: Перераход в деньгах | D37: =C33-D36 -> -10295803 | F37: Перераход в деньгах | H37: =G33-H36 -> -2043155.3 | AD37: Смарт–Сэйл | AE37: =AM8 -> 1494137 | AF37: =G72 -> 270412 | AG37: =AF37/AE37 -> 0.18098207 | AI37: =G75 | AJ37: =AG37 -> 0.18098207 | AK37: =AJ37/AI37-1 -> #DIV/0!
K38: Распределение по направлениям | M38: =SUM(M40:N40)/$L$40 -> 0.27803209 | O38: =SUM(O40:P40)/$L$40 -> 0.70472859 | Q38: =SUM(Q40:R40)/$L$40 -> 0.010120908 | S38: =SUM(S40:T40)/$L$40 -> 0.0030393827 | U38: =SUM(U40:V40)/$L$40 -> 0.0038262878 | W38: =SUM(W40:X40)/$L$40 -> 0.00025273424 | Y38: =SUM(Y40:Z40)/$L$40 -> 0 | AC38: Летуаль | AD38: Биг–Л | AE38: =AM9 -> 490176 | AF38: 0 | AG38: =AF38/AE38 -> 0 | AI38: =C91 -> 0.1 | AJ38: =AG38 -> 0 | AK38: =AJ38/AI38-1 -> -1
B39: План | D39: =O42 -> 2.0608031e+08 | F39: План | H39: =P42 -> 1.1437699e+08 | K39: Распределение продаж | L39: =L40/$L$40 -> 1 | M39: =M40/$L$40 -> 0.1553855 | N39: =N40/$L$40 -> 0.1226466 | O39: =O40/$L$40 -> 0.50031573 | P39: =P40/$L$40 -> 0.20441286 | Q39: =Q40/$L$40 -> 0.0075475279 | R39: =R40/$L$40 -> 0.0025733801 | S39: =S40/$L$40 -> 0.0008442393 | ... AA39: =AA40/$L$40 -> 0 | AD39: Смарт–Сэйл | AE39: =AM10 -> 1274528 | AF39: 0 | AG39: =AF39/AE39 -> 0 | AI39: =G91 -> 0.1 | AJ39: =AG39 -> 0 | AK39: =AJ39/AI39-1 -> -1
B40: Плато продаж | D40: =D34/$C$1 -> 11172678 | F40: Плато продаж | H40: =H34/$C$1 -> 4564795.7 | K40: Прогноз | L40: =L35/$C$1*$G$1 -> 692268905 | M40: =M35/$C$1*$G$1 -> 1.0756855e+08 | N40: =N35/$C$1*$G$1 -> 84904425 | O40: =O35/$C$1*$G$1 -> 3.4635303e+08 | P40: =P35/$C$1*$G$1 -> 1.4150867e+08 | Q40: =Q35/$C$1*$G$1 -> 5224918.8 | R40: =R35/$C$1*$G$1 -> 1781471 | S40: =S35/$C$1*$G$1 -> 584440.62 | ... AA40: =AA35/$C$1*$G$1 -> 0 | AC40: Золотое Яблоко | AD40: Биг–Л | AE40: =AM11 -> 100903 | AF40: 0 | AG40: =AF40/AE40 -> 0 | AI40: 0 | AJ40: =AG40 -> 0 | AK40: =AJ40/AI40-1 -> #DIV/0!
...

Sheet Февраль 26
A1: 3 | B1: Вчера | C1: 28 | F1: Дней в месяце | G1: 28
A2: Актуально на | B2: 45988 | M2: Оз | O2: Вб | Q2: Ям | S2: Лету | U2: ЗЯ | W2: Магнит Маркет | Y2: Сайт | AE2: план | AF2: ауты | AG2: реальный план | AI2: выручка | AJ2: отказы/возвраты | AK2: раздачи | AL2: выкупы | AM2: реальная выручка
B3: Ozon | M3: Биг–Л | N3: Смарт | O3: Биг–Л | P3: Смарт | Q3: Биг–Л | R3: Смарт | S3: Биг–Л | T3: Смарт | U3: Биг–Л | V3: Смарт | W3: Биг–Л | X3: Смарт | Y3: qeep | Z3: harly | AA3: Алтея | AC3: WB | AD3: Биг–Л | AE3: =D39 -> 199495328 | AG3: =AE3-AF3 -> 199495328 | AI3: =O35 -> 2.0608031e+08 | AM3: =AI3-SUM(AJ3:AL3) -> 2.0608031e+08
B4: Биг–Л / Февраль | до | D4: =TODAY()-1 -> 46107 | F4: Смарт/ Февраль| до | H4: =$D$4 -> 46107 | K4: 46054 | L4: =SUM(M4:AA4) -> 22380818 | M4: 5372144 | N4: 2769431 | O4: 7651982 | P4: 6259469 | Q4: 102903 | R4: 81221 | S4: 9901 | T4: 68464 | U4: 10862 | V4: 53890 | W4: 0 | X4: 551 | AD4: Смарт–Сэйл | AE4: =H39 -> 138055387 | AG4: =AE4-AF4 -> 138055387 | AI4: =P35 -> 1.1437699e+08 | AM4: =AI4-SUM(AJ4:AL4) -> 1.1437699e+08
A5: =IFERROR(C5/$C$15, " ") -> 0.89654243 | B5: Оплата за клик | C5: 13483878 | F5: Оплата за клик | G5: 10577282 | I5: =IFERROR(G5/$G$15, " ") -> 0.95763547 | K5: 46055 | L5: =SUM(M5:AA5) -> 18252037 | M5: 4368346 | N5: 2553900 | O5: 7276839 | P5: 3722942 | Q5: 107801 | R5: 118624 | S5: 7429 | T5: 44509 | U5: 9858 | V5: 41789 | W5: 0 | X5: 0 | AC5: Ozon | AD5: Биг–Л | AE5: =D21 -> 110647711 | AG5: =AE5-AF5 -> 110647711 | AI5: =M35 -> 105053826 | AM5: =AI5-SUM(AJ5:AL5) -> 105053826
A6: =IFERROR(C6/$C$15, " ") -> 0.0036552187 | B6: Оплата за заказ | C6: 54974 | F6: Оплата за заказ | G6: 179988 | I6: =IFERROR(G6/$G$15, " ") -> 0.016295575 | K6: 46056 | L6: =SUM(M6:AA6) -> 17986720 | M6: 4679661 | N6: 2818473 | O6: 6841463 | P6: 3302445 | Q6: 127025 | R6: 95317 | S6: 6880 | T6: 64340 | U6: 8993 | V6: 39046 | W6: 522.5 | X6: 2554.35 | AD6: Смарт–Сэйл | AE6: =H21 -> 80715472 | AG6: =AE6-AF6 -> 80715472 | AI6: =N35 -> 84254055 | AM6: =AI6-SUM(AJ6:AL6) -> 84254055
A7: =IFERROR(C7/$C$15, " ") -> 0.087439476 | B7: Медийка | C7: 1315078 | F7: Медийка | G7: 144385 | I7: =IFERROR(G7/$G$15, " ") -> 0.013072186 | K7: 46057 | L7: =SUM(M7:AA7) -> 17866750 | M7: 3988192 | N7: 2391656 | O7: 7177214 | P7: 3991472 | Q7: 109509 | R7: 104352 | S7: 11272 | T7: 46619 | U7: 11974 | V7: 34490 | W7: 0 | X7: 0 | AC7: ЯМаркет | AD7: Биг–Л | AE7: =D78 -> 3639698 | AG7: =AE7-AF7 -> 3639698 | AI7: =Q35 -> 3069853 | AM7: =AI7-SUM(AJ7:AL7) -> 3069853
A8: =IFERROR(C8/$C$15, " ") -> 0 | B8: Баллы за отзывы | C8: 0 | F8: Баллы за отзывы | G8: 1464 | I8: =IFERROR(G8/$G$15, " ") -> 0.00013254618 | K8: 46058 | L8: =SUM(M8:AA8) -> 19204974 | M8: 4047129 | N8: 2860213.1 | O8: 7304220 | P8: 4593798 | Q8: 168079 | R8: 87609 | S8: 16753 | T8: 42853 | U8: 15881 | V8: 64363 | W8: 2038.3 | X8: 2038 | AD8: Смарт–Сэйл | AE8: =H78 -> 2771328 | AG8: =AE8-AF8 -> 2771328 | AI8: =R35 -> 2257611 | AM8: =AI8-SUM(AJ8:AL8) -> 2257611
A9: =IFERROR(C9/$C$15, " ") -> 0.012204165 | B9: Бонусы продавца | C9: 183549 | F9: Бонусы продавца | G9: 142088 | I9: =IFERROR(G9/$G$15, " ") -> 0.012864222 | K9: 46059 | L9: =SUM(M9:AA9) -> 19252449 | M9: 4018207 | N9: 2954370.1 | O9: 7210530 | P9: 4716662 | Q9: 141692 | R9: 72584 | S9: 18005 | T9: 62434 | U9: 16359 | V9: 37574 | W9: 2830 | X9: 1202 | AC9: Летуаль | AD9: Биг–Л | AE9: =S42 -> 355446 | AG9: =AE9-AF9 -> 355446 | AI9: =S35 -> 619304 | AM9: =AI9-SUM(AJ9:AL9) -> 619304
A10: =IFERROR(C10/$C$15, " ") -> 0 | B10: Рассылки | C10: 0 | F10: Рассылки | I10: =IFERROR(G10/$G$15, " ") -> 0 | K10: 46060 | L10: =SUM(M10:AA10) -> 19269758 | M10: 3597521 | N10: 2791137.1 | O10: 7447201 | P10: 5027386 | Q10: 135696 | R10: 101265 | S10: 32554 | T10: 56939 | U10: 17159 | V10: 58983 | W10: 2680.65 | X10: 1236.15 | AD10: Смарт–Сэйл | AE10: =T42 -> 1486093 | AG10: =AE10-AF10 -> 1486093 | AI10: =T35 -> 1719666 | AM10: =AI10-SUM(AJ10:AL10) -> 1719666
A11: =IFERROR(C11/$C$15, " ") -> 0 | B11: Закрепление отзыва | C11: 0 | F11: Закрепление отзыва | I11: =IFERROR(G11/$G$15, " ") -> 0 | K11: 46061 | L11: =SUM(M11:AA11) -> 21288492 | M11: 3925173 | N11: 3399460.9 | O11: 8317863 | P11: 5272869 | Q11: 103297 | R11: 82209 | S11: 27343 | T11: 83038 | U11: 7335 | V11: 64213 | W11: 2899.95 | X11: 2791.65 | AC11: Золотое Яблоко | AD11: Биг–Л | AE11: =U42 -> 594263 | AG11: =AE11-AF11 -> 594263 | AI11: =U35 -> 141359 | AM11: =AI11-SUM(AJ11:AL11) -> 141359
B12: Иные электронные услуги | C12: 0 | F12: Иные электронные услуги | I12: =IFERROR(G12/$G$15, " ") -> 0 | K12: 46062 | L12: =SUM(M12:AA12) -> 19834724 | M12: 4011785 | N12: 4258828.4 | O12: 7284229 | P12: 3949382 | Q12: 72535 | R12: 87159 | S12: 31309 | T12: 81620 | U12: 8070 | V12: 49506 | W12: 0 | X12: 300.9 | AD12: Смарт–Сэйл | AE12: =V42 -> 954144 | AG12: =AE12-AF12 -> 954144 | AI12: =V35 -> 1599107 | AM12: =AI12-SUM(AJ12:AL12) -> 1599107
B13: Продвижение бренда | C13: 0 | F13: Продвижение бренда | I13: =IFERROR(G13/$G$15, " ") -> 0 | K13: 46063 | L13: =SUM(M13:AA13) -> 19306307 | M13: 3765396 | N13: 3473043 | O13: 7763233 | P13: 3903031 | Q13: 112806 | R13: 78188 | S13: 43065 | T13: 82671 | U13: 6499 | V13: 68985 | W13: 3685 | X13: 5705.25 | AD13: итог | AE13: =SUM(AE3:AE12) -> 5.3871487e+08 | AF13: =SUM(AF3:AF12) -> 0 | AG13: =SUM(AG3:AG12) -> 5.3871487e+08 | AI13: =SUM(AI3:AI12) -> 5.1917208e+08 | AJ13: =SUM(AJ3:AJ12) -> 0 | AK13: =SUM(AK3:AK12) -> 0 | AL13: =SUM(AL3:AL12) -> 0 | AM13: =SUM(AM3:AM12) -> 5.1917208e+08
B14: Ozon Рассрочка | C14: 2387 | F14: Ozon Рассрочка | K14: 46064 | L14: =SUM(M14:AA14) -> 18578760 | M14: 3627716 | N14: 3122784.5 | O14: 7461659 | P14: 3983616 | Q14: 119984 | R14: 91511 | S14: 43373 | T14: 53458 | U14: 2986 | V14: 68405 | W14: 1192.5 | X14: 2075
B15: Итого расходов | C15: =SUM(C5:C14) -> 15039866 | F15: Итого расходов | G15: =SUM(G5:G14) -> 11045207 | H15: =SUM(H5:H14) -> 0 | K15: 46065 | L15: =SUM(M15:AA15) -> 19675120 | M15: 3805866 | N15: 3383037.1 | O15: 7811860 | P15: 4297347 | Q15: 102139 | R15: 93039 | S15: 42722 | T15: 73921 | U15: 3146 | V15: 58589 | W15: 0 | X15: 3454
B16: Выручка | D16: =M35 -> 105053826 | F16: Выручка | H16: =N35 -> 84254055 | K16: 46066 | L16: =SUM(M16:AA16) -> 18815684 | M16: 3709816 | N16: 3562179 | O16: 7042533 | P16: 4074817 | Q16: 130371 | R16: 72650 | S16: 68327 | T16: 76897 | U16: 3171 | V16: 65863 | W16: 4897 | X16: 4163
B17: ДРР / Факт | D17: =C15/D16 -> 0.14316343 | F17: ДРР / Факт | H17: =G15/H16 -> 0.13109407 | K17: 46067 | L17: =SUM(M17:AA17) -> 17567891 | M17: 3629820 | N17: 3051682 | O17: 6742154 | P17: 3796162 | Q17: 109704 | R17: 79200 | S17: 41974 | T17: 48212 | U17: 1243 | V17: 67329 | W17: 0 | X17: 411 | AE17: Без вычетов | AI17: С вычетом всего
A18: =D17/C18 -> 0.95442286 | B18: ДРР / План | C18: 0.15 | D18: =D16*C18 -> 15758074 | F18: ДРР / План | G18: 0.13 | H18: =H16*G18 -> 10953027 | I18: =H17/G18 -> 1.0084159 | K18: 46068 | L18: =SUM(M18:AA18) -> 19726431 | M18: 3578944 | N18: 3280752 | O18: 8138150 | P18: 4331470 | Q18: 151378 | R18: 62711 | S18: 25886 | T18: 78643 | U18: 2302 | V18: 71783 | W18: 1150 | X18: 3261.8 | AE18: план | AF18: выручка | AG18: дельта | AI18: реальный план | AJ18: реальная выручка | AK18: дельта
B19: Перерасход в деньгах | D19: =C15-D18 -> -718207.9 | F19: Перераход в деньгах | H19: =G15-H18 -> 92179.824 | K19: 46069 | L19: =SUM(M19:AA19) -> 16983888 | M19: 3456749 | N19: 2778825 | O19: 6920459 | P19: 3469239 | Q19: 111219 | R19: 85493 | S19: 22261 | T19: 65822 | U19: 3325 | V19: 63582 | W19: 4686.29 | X19: 2227.69 | AC19: WB | AD19: Биг–Л | AE19: =AE3 -> 199495328 | AF19: =AI3 -> 2.0608031e+08 | AG19: =IFERROR(AF19/AE19, " ") -> 1.0330082 | AI19: =AG3 -> 199495328 | AJ19: =AM3 -> 2.0608031e+08 | AK19: =IFERROR(AJ19/AI19, " ") -> 1.0330082
K20: 46070 | L20: =SUM(M20:AA20) -> 16243698 | M20: 3509490 | N20: 2856296 | O20: 6445829 | P20: 3155216 | Q20: 83133 | R20: 51078 | S20: 22261 | T20: 50830 | U20: 1334 | V20: 59686 | W20: 1073.63 | X20: 7471.59 | AD20: Смарт–Сэйл | AE20: =AE4 -> 138055387 | AF20: =AI4 -> 1.1437699e+08 | AG20: =IFERROR(AF20/AE20, " ") -> 0.82848624 | AI20: =AG4 -> 138055387 | AJ20: =AM4 -> 1.1437699e+08 | AK20: =IFERROR(AJ20/AI20, " ") -> 0.82848624
B21: План | D21: =M42 -> 110647711 | F21: План | H21: =N42 -> 80715472 | K21: 46071 | L21: =SUM(M21:AA21) -> 17429785 | M21: 3662400 | N21: 2793781 | O21: 7322126 | P21: 3330989 | Q21: 102799 | R21: 86473 | S21: 14371 | T21: 53023 | U21: 3458 | V21: 51663 | W21: 3141.14 | X21: 5560.75 | AC21: Ozon | AD21: Биг–Л | AE21: =AE5 -> 110647711 | AF21: =AI5 -> 105053826 | AG21: =IFERROR(AF21/AE21, " ") -> 0.94944419 | AI21: =AG5 -> 110647711 | AJ21: =AM5 -> 105053826 | AK21: =IFERROR(AJ21/AI21, " ") -> 0.94944419
B22: Плато продаж | D22: =D16/$C$1 -> 3751922.4 | F22: Плато продаж | H22: =H16/$C$1 -> 3009073.4 | K22: 46072 | L22: =SUM(M22:AA22) -> 16646958 | M22: 3316224 | N22: 2724931 | O22: 6735823 | P22: 3574250 | Q22: 70209 | R22: 73933 | S22: 14399 | T22: 68151 | U22: 1334 | V22: 60674 | W22: 4255.47 | X22: 2774.15 | AD22: Смарт–Сэйл | AE22: =AE6 -> 80715472 | AF22: =AI6 -> 84254055 | AG22: =IFERROR(AF22/AE22, " ") -> 1.0438402 | AI22: =AG6 -> 80715472 | AJ22: =AM6 -> 84254055 | AK22: =IFERROR(AJ22/AI22, " ") -> 1.0438402
B23: Нужно сделать на вчера | D23: =D21/$G$1*$C$1 -> 110647711 | F23: Нужно сделать на вчера | H23: =H21/$G$1*$C$1 -> 80715472 | K23: 46073 | L23: =SUM(M23:AA23) -> 17953625 | M23: 3659255 | N23: 2991282.1 | O23: 6372463 | P23: 4658057 | Q23: 98858 | R23: 45473 | S23: 9943 | T23: 51014 | U23: 3998 | V23: 52311 | W23: 4799.27 | X23: 6172.05 | AC23: ЯМаркет | AD23: Биг–Л | AE23: =AE7 -> 3639698 | AF23: =AI7 -> 3069853 | AG23: =IFERROR(AF23/AE23, " ") -> 0.84343619 | AI23: =AG7 -> 3639698 | AJ23: =AM7 -> 3069853 | AK23: =IFERROR(AJ23/AI23, " ") -> 0.84343619
B24: Нужно делать в день | D24: =(D21-D16)/($G$1-$C$1) -> #DIV/0! | F24: Нужно делать в день | H24: =(H21-H16)/($G$1-$C$1) -> #DIV/0! | K24: 46074 | L24: =SUM(M24:AA24) -> 16345828 | M24: 3546840 | N24: 2829425 | O24: 6644788 | P24: 3108943 | Q24: 11248 | R24: 67592 | S24: 5464 | T24: 52171 | U24: 0 | V24: 61796 | W24: 2723.4 | X24: 14837.98 | AD24: Смарт–Сэйл | AE24: =AE8 -> 2771328 | AF24: =AI8 -> 2257611 | AG24: =IFERROR(AF24/AE24, " ") -> 0.81463147 | AI24: =AG8 -> 2771328 | AJ24: =AM8 -> 2257611 | AK24: =IFERROR(AJ24/AI24, " ") -> 0.81463147
B25: Дельта от плана | D25: =D16-D23 -> -5593885 | F25: Дельта от плана | H25: =H16-H23 -> 3538582.7 | K25: 46075 | L25: =SUM(M25:AA25) -> 18314277 | M25: 3445861 | N25: 3335429 | O25: 7327483 | P25: 3884241 | Q25: 119345 | R25: 61954 | S25: 8515 | T25: 77844 | U25: 0 | V25: 46057 | W25: 4026.27 | X25: 3521.69 | AC25: Летуаль | AD25: Биг–Л | AE25: =AE9 -> 355446 | AF25: =AI9 -> 619304 | AG25: =IFERROR(AF25/AE25, " ") -> 1.7423294 | AI25: =AG9 -> 355446 | AJ25: =AM9 -> 619304 | AK25: =IFERROR(AJ25/AI25, " ") -> 1.7423294
B26: Прогноз по выручке | D26: =D16/$C$1*$G$1 -> 105053826 | F26: Прогноз по выручке | H26: =H16/$C$1*$G$1 -> 84254055 | K26: 46076 | L26: =SUM(M26:AA26) -> 20182913 | M26: 3626455 | N26: 3158305.7 | O26: 8114736 | P26: 4977826 | Q26: 123444 | R26: 71588 | S26: 5464 | T26: 52202 | U26: 0 | V26: 31860 | W26: 7399.07 | X26: 13633.05 | AD26: Смарт–Сэйл | AE26: =AE10 -> 1486093 | AF26: =AI10 -> 1719666 | AG26: =IFERROR(AF26/AE26, " ") -> 1.1571725 | AI26: =AG10 -> 1486093 | AJ26: =AM10 -> 1719666 | AK26: =IFERROR(AJ26/AI26, " ") -> 1.1571725
B27: Прогноз по выручке (%) | D27: =D26/D21 -> 0.94944419 | F27: Прогноз по выручке (%) | H27: =H26/H21 -> 1.0438402 | K27: 46077 | L27: =SUM(M27:AA27) -> 18083192 | M27: 3380035 | N27: 2790555.1 | O27: 7879010 | P27: 3725965 | Q27: 100191 | R27: 80650 | S27: 11069 | T27: 55503 | U27: 2072 | V27: 50611 | W27: 3002.2 | X27: 4528.4 | AC27: Золотое Яблоко | AD27: Биг–Л | AE27: =AE11 -> 594263 | AF27: =AI11 -> 141359 | AG27: =IFERROR(AF27/AE27, " ") -> 0.23787279 | AI27: =AG11 -> 594263 | AJ27: =AM11 -> 141359 | AK27: =IFERROR(AJ27/AI27, " ") -> 0.23787279
K28: 46078 | L28: =SUM(M28:AA28) -> 18672838 | M28: 3622040 | N28: 2976212.1 | O28: 7904447 | P28: 3828920 | Q28: 119847 | R28: 80911 | S28: 20222 | T28: 59756 | U28: 0 | V28: 45359 | W28: 6573.56 | X28: 8550.24 | AD28: Смарт–Сэйл | AE28: =AE12 -> 954144 | AF28: =AI12 -> 1599107 | AG28: =IFERROR(AF28/AE28, " ") -> 1.6759598 | AI28: =AG12 -> 954144 | AJ28: =AM12 -> 1599107 | AK28: =IFERROR(AJ28/AI28, " ") -> 1.6759598
B29: Wildberries / Расход бонусы + рубли | K29: 46079 | L29: =SUM(M29:AA29) -> 18178155 | M29: 3491165 | N29: 2973035 | O29: 7591972 | P29: 3818584 | Q29: 81534 | R29: 74568 | S29: 17164 | T29: 44107 | U29: 0 | V29: 73990 | W29: 3658.51 | X29: 8377.93 | AE29: =SUM(AE19:AE28) -> 5.3871487e+08 | AF29: =SUM(AF19:AF28) -> 5.1917208e+08 | AG29: =IFERROR(AF29/AE29, " ") -> 0.96372332 | AI29: =SUM(AI19:AI24) -> 5.3532492e+08 | AJ29: =SUM(AJ19:AJ24) -> 5.1509265e+08 | AK29: =IFERROR(AJ29/AI29, " ") -> 0.96220562
B30: =B4 -> Биг–Л / Февраль | до | D30: =$D$4 -> 46107 | F30: =F4 -> Смарт/ Февраль| до | H30: =$D$4 -> 46107 | K30: 46080 | L30: =SUM(M30:AA30) -> 17083965 | M30: 3060688 | N30: 2685352 | O30: 7317169 | P30: 3643196 | Q30: 124962 | R30: 78003 | S30: 24396 | T30: 56772 | U30: 0 | V30: 86140 | W30: 1212 | X30: 6075
A31: =IFERROR(C31/$C$33, " ") -> 0.87143112 | B31: Затраты из РК | C31: 8602065 | F31: Затраты из РК | G31: 6013051 | I31: =IFERROR(G31/$G$33, " ") -> 0.97315757 | K31: 46081 | L31: =SUM(M31:AA31) -> 18244654 | M31: 3150908 | N31: 2689679 | O31: 8032879.2 | P31: 3978695.1 | Q31: 128145 | R31: 92256 | S31: 16982 | T31: 67853 | U31: 0 | V31: 70570 | W31: 8197.76 | X31: 8489.04 | AC31: Только рубли | AE31: реальная выручка | AF31: реклама | AG31: ДРР | AI31: ДРР план | AJ31: ДРР факт | AK31: дельта
A32: =IFERROR(C32/$C$33, " ") -> 0.12856888 | B32: Отзывы за баллы | C32: 1269128.3 | F32: Отзывы за баллы | G32: 165856.9 | I32: =IFERROR(G32/$G$33, " ") -> 0.02684243 | L32: =SUM(M32:AA32) -> 0 | AC32: WB | AD32: Биг–Л | AE32: =AM3 -> 2.0608031e+08 | AF32: =C51 -> 0 | AG32: =AF32/AE32 -> 0 | AI32: =C36 -> 0.08 | AJ32: =AG32 -> 0 | AK32: =AJ32/AI32-1 -> -1
B33: Итого расходов | C33: =SUM(C31:C32) -> 9871193.3 | F33: Итого расходов | G33: =SUM(G31:G32) -> 6178907.9 | L33: =SUM(M33:AA33) -> 0 | AD33: Смарт–Сэйл | AE33: =AM4 -> 1.1437699e+08 | AF33: =G51 -> 0 | AG33: =AF33/AE33 -> 0 | AI33: =G36 -> 0.08 | AJ33: =AG33 -> 0 | AK33: =AJ33/AI33-1 -> -1
B34: Выручка | D34: =O35 -> 2.0608031e+08 | F34: Выручка | H34: =P35 -> 1.1437699e+08 | L34: =SUM(M34:AA34) -> 0 | AC34: Ozon | AD34: Биг–Л | AE34: =AM5 -> 105053826 | AF34: =C15 -> 15039866 | AG34: =AF34/AE34 -> 0.14316343 | AI34: =C18 -> 0.15 | AJ34: =AG34 -> 0.14316343 | AK34: =AJ34/AI34-1 -> -0.045577137
B35: ДРР / Факт | D35: =C33/D34 -> 0.047899739 | F35: ДРР / Факт | H35: =G33/H34 -> 0.054022299 | K35: =L35/C1 -> 18548953 | L35: =SUM(L4:L34) -> 5.1937069e+08 | M35: =SUM(M4:M34) -> 105053826 | N35: =SUM(N4:N34) -> 84254055 | O35: =SUM(O4:O34) -> 2.0608031e+08 | P35: =SUM(P4:P34) -> 1.1437699e+08 | Q35: =SUM(Q4:Q34) -> 3069853 | R35: =SUM(R4:R34) -> 2257611 | S35: =SUM(S4:S34) -> 619304 | ... AA35: =SUM(AA4:AA34) -> 0 | AD35: Смарт–Сэйл | AE35: =AM6 -> 84254055 | AF35: =G15 -> 11045207 | AG35: =AF35/AE35 -> 0.13109407 | AI35: =G18 -> 0.13 | AJ35: =AG35 -> 0.13109407 | AK35: =AJ35/AI35-1 -> 0.0084159221
A36: =D35/C36 -> 0.59874674 | B36: ДРР / План | C36: 0.08 | D36: =D34*C36 -> 16486425 | F36: ДРР / План | G36: 0.08 | H36: =H34*G36 -> 9150159.1 | I36: =H35/G36 -> 0.67527874 | M36: =M35/$L$35 -> 0.20227138 | N36: =N35/$L$35 -> 0.16222335 | O36: =O35/$L$35 -> 0.39678849 | P36: =P35/$L$35 -> 0.22022226 | Q36: =Q35/$L$35 -> 0.0059107166 | R36: =R35/$L$35 -> 0.0043468202 | S36: =S35/$L$35 -> 0.0011924123 | T36: =T35/$L$35 -> 0.0033110571 | ... AA36: =AA35/$L$35 -> 0 | AC36: ЯМаркет | AD36: Биг–Л | AE36: =AM7 -> 3069853 | AF36: =C72 -> 585970 | AG36: =AF36/AE36 -> 0.19087885 | AI36: =C75 -> 0.18 | AJ36: =AG36 -> 0.19087885 | AK36: =AJ36/AI36-1 -> 0.060438037
B37: Перераход в деньгах | D37: =C33-D36 -> -6615231.8 | F37: Перераход в деньгах | H37: =G33-H36 -> -2971251.2 | AD37: Смарт–Сэйл | AE37: =AM8 -> 2257611 | AF37: =G72 -> 437052 | AG37: =AF37/AE37 -> 0.19359048 | AI37: =G75 -> 0.175 | AJ37: =AG37 -> 0.19359048 | AK37: =AJ37/AI37-1 -> 0.10623132
K38: Распределение по направлениям | M38: =SUM(M40:N40)/$L$40 -> 0.36449473 | O38: =SUM(O40:P40)/$L$40 -> 0.61701076 | Q38: =SUM(Q40:R40)/$L$40 -> 0.010257537 | S38: =SUM(S40:T40)/$L$40 -> 0.0045034694 | U38: =SUM(U40:V40)/$L$40 -> 0.0033511055 | W38: =SUM(W40:X40)/$L$40 -> 0.0003824015 | Y38: =SUM(Y40:Z40)/$L$40 -> 0 | AC38: Летуаль | AD38: Биг–Л | AE38: =AM9 -> 619304 | AF38: 0 | AG38: =AF38/AE38 -> 0 | AI38: =C91 -> 0.1 | AJ38: =AG38 -> 0 | AK38: =AJ38/AI38-1 -> -1
B39: План | D39: =O42 -> 199495328 | F39: План | H39: =P42 -> 138055387 | K39: Распределение продаж | L39: =L40/$L$40 -> 1 | M39: =M40/$L$40 -> 0.20227138 | N39: =N40/$L$40 -> 0.16222335 | O39: =O40/$L$40 -> 0.39678849 | P39: =P40/$L$40 -> 0.22022226 | Q39: =Q40/$L$40 -> 0.0059107166 | R39: =R40/$L$40 -> 0.0043468202 | S39: =S40/$L$40 -> 0.0011924123 | ... AA39: =AA40/$L$40 -> 0 | AD39: Смарт–Сэйл | AE39: =AM10 -> 1719666 | AF39: 0 | AG39: =AF39/AE39 -> 0 | AI39: =G91 -> 0.1 | AJ39: =AG39 -> 0 | AK39: =AJ39/AI39-1 -> -1
B40: Плато продаж | D40: =D34/$C$1 -> 7360011.2 | F40: Плато продаж | H40: =H34/$C$1 -> 4084892.5 | K40: Прогноз | L40: =L35/$C$1*$G$1 -> 5.1937069e+08 | M40: =M35/$C$1*$G$1 -> 105053826 | N40: =N35/$C$1*$G$1 -> 84254055 | O40: =O35/$C$1*$G$1 -> 2.0608031e+08 | P40: =P35/$C$1*$G$1 -> 1.1437699e+08 | Q40: =Q35/$C$1*$G$1 -> 3069853 | R40: =R35/$C$1*$G$1 -> 2257611 | S40: =S35/$C$1*$G$1 -> 619304 | ... AA40: =AA35/$C$1*$G$1 -> 0 | AC40: Золотое Яблоко | AD40: Биг–Л | AE40: =AM11 -> 141359 | AF40: 0 | AG40: =AF40/AE40 -> 0 | AI40: 0 | AJ40: =AG40 -> 0 | AK40: =AJ40/AI40-1 -> #DIV/0!
...

Sheet Январь 26
A1: 3 | B1: Вчера | C1: 31 | F1: Дней в месяце | G1: 31
A2: Актуально на | B2: 45988 | M2: Оз | O2: Вб | Q2: Ям | S2: Лету | U2: ЗЯ | W2: Магнит Маркет | Y2: Сайт | AE2: план | AF2: ауты | AG2: реальный план | AI2: выручка | AJ2: отказы/возвраты | AK2: раздачи | AL2: выкупы | AM2: реальная выручка
B3: Ozon | M3: Биг–Л | N3: Смарт | O3: Биг–Л | P3: Смарт | Q3: Биг–Л | R3: Смарт | S3: Биг–Л | T3: Смарт | U3: Биг–Л | V3: Смарт | W3: Биг–Л | X3: Смарт | Y3: qeep | Z3: harly | AA3: Алтея | AC3: WB | AD3: Биг–Л | AE3: =D39 -> 113971735 | AG3: =AE3-AF3 -> 113971735 | AI3: =O35 -> 199495328 | AK3: =13501+762213 -> 775714 | AM3: =AI3-SUM(AJ3:AL3) -> 198719614
B4: Биг–Л / Январь | до | D4: 46053 | F4: Смарт/ Январь| до | H4: =$D$4 -> 46053 | K4: 46023 | L4: =SUM(M4:AA4) -> 10758032 | M4: 2560744 | N4: 1562108 | O4: 4229443 | P4: 2168992 | Q4: 98667 | R4: 46740 | S4: 2057 | T4: 45718 | U4: 1399 | V4: 42164 | W4: 0 | X4: 0 | Y4: 0 | AD4: Смарт–Сэйл | AE4: =H39 -> 110544589 | AG4: =AE4-AF4 -> 110544589 | AI4: =P35 -> 138055387 | AK4: =13766+940304 -> 954070 | AM4: =AI4-SUM(AJ4:AL4) -> 137101317
A5: =IFERROR(C5/$C$15, " ") -> 0.92309184 | B5: Оплата за клик | C5: 14024803 | F5: Оплата за клик | G5: 9067823 | I5: =IFERROR(G5/$G$15, " ") -> 0.94906971 | K5: 46024 | L5: =SUM(M5:AA5) -> 14913776 | M5: 3453779 | N5: 2177124 | O5: 5623274 | P5: 3361853 | Q5: 127362 | R5: 71748 | S5: 710 | T5: 54536 | U5: 2798 | V5: 39410 | W5: 0 | X5: 0 | Y5: 1182 | AC5: Ozon | AD5: Биг–Л | AE5: =D21 -> 96599698 | AG5: =AE5-AF5 -> 96599698 | AI5: =M35 -> 110647711 | AJ5: =AI5/80962*(6339+107) -> 8809505 | AK5: =15257+466756 -> 482013 | AM5: =AI5-SUM(AJ5:AL5) -> 101356193
A6: =IFERROR(C6/$C$15, " ") -> 0.027410783 | B6: Оплата за заказ | C6: 416460 | F6: Оплата за заказ | G6: 184960 | I6: =IFERROR(G6/$G$15, " ") -> 0.019358553 | K6: 46025 | L6: =SUM(M6:AA6) -> 15612171 | M6: 3710342 | N6: 2148368 | O6: 5297359 | P6: 4115128 | Q6: 131603 | R6: 86801 | S6: 4325 | T6: 54824 | U6: 6121 | V6: 55878 | W6: 0 | X6: 1422 | Y6: 0 | AD6: Смарт–Сэйл | AE6: =H21 -> 86342890 | AG6: =AE6-AF6 -> 86342890 | AI6: =N35 -> 80715472 | AJ6: =AI6/74719*(4982+97) -> 5486608.3 | AK6: =531+520719 -> 521250 | AM6: =AI6-SUM(AJ6:AL6) -> 74707614
A7: =IFERROR(C7/$C$15, " ") -> 0.037284417 | B7: Медийка | C7: 566473 | F7: Медийка | G7: 168528 | I7: =IFERROR(G7/$G$15, " ") -> 0.017638723 | K7: 46026 | L7: =SUM(M7:AA7) -> 15957648 | M7: 3924482 | N7: 2310076 | O7: 5439555 | P7: 3953389 | Q7: 129200 | R7: 109900 | S7: 2345 | T7: 39288 | U7: 6837 | V7: 40020 | W7: 0 | X7: 1017 | Y7: 1539 | AC7: ЯМаркет | AD7: Биг–Л | AE7: =D78 -> 3741104 | AG7: =AE7-AF7 -> 3741104 | AI7: =Q35 -> 3639698 | AJ7: =AI7/3564*(459+7) -> 475897.66 | AK7: =2520+11217 -> 13737 | AM7: =AI7-SUM(AJ7:AL7) -> 3150063.3
A8: =IFERROR(C8/$C$15, " ") -> 1.9284828e-05 | B8: Баллы за отзывы | C8: 293 | F8: Баллы за отзывы | G8: 2416 | I8: =IFERROR(G8/$G$15, " ") -> 0.00025286692 | K8: 46027 | L8: =SUM(M8:AA8) -> 15762072 | M8: 3770933 | N8: 2366459 | O8: 5510412 | P8: 3845833 | Q8: 105654 | R8: 73717 | S8: 2499 | T8: 39729 | U8: 12117 | V8: 32364 | W8: 0 | X8: 2355 | Y8: 0 | AD8: Смарт–Сэйл | AE8: =H78 -> 3478652 | AG8: =AE8-AF8 -> 3478652 | AI8: =R35 -> 2771328 | AJ8: =AI8/3587*(313+4) -> 244915.24 | AK8: =17845 -> 17845 | AM8: =AI8-SUM(AJ8:AL8) -> 2508567.8
A9: =IFERROR(C9/$C$15, " ") -> 0.011964031 | B9: Бонусы продавца | C9: 181773 | F9: Бонусы продавца | G9: 130706 | I9: =IFERROR(G9/$G$15, " ") -> 0.013680142 | K9: 46028 | L9: =SUM(M9:AA9) -> 15506133 | M9: 3908307 | N9: 2397154.1 | O9: 5188588 | P9: 3742674 | Q9: 89656 | R9: 112022 | S9: 0 | T9: 30184 | U9: 10552 | V9: 25808 | W9: 0 | X9: 1188 | Y9: 0 | AC9: Летуаль | AD9: Биг–Л | AE9: =S42 -> 341575 | AG9: =AE9-AF9 -> 341575 | AI9: =S35 -> 355446 | AM9: =AI9-SUM(AJ9:AL9) -> 355446
A10: =IFERROR(C10/$C$15, " ") -> 0 | B10: Рассылки | C10: 0 | F10: Рассылки | I10: =IFERROR(G10/$G$15, " ") -> 0 | K10: 46029 | L10: =SUM(M10:AA10) -> 17363056 | M10: 4793004 | N10: 2326980 | O10: 5856182 | P10: 4156421 | Q10: 99819 | R10: 62851 | S10: 3675 | T10: 21380 | U10: 11642 | V10: 28993 | W10: 0 | X10: 2109 | Y10: 0 | AD10: Смарт–Сэйл | AE10: =T42 -> 1332348 | AG10: =AE10-AF10 -> 1332348 | AI10: =T35 -> 1486093 | AK10: =9113 -> 9113 | AM10: =AI10-SUM(AJ10:AL10) -> 1476980
A11: =IFERROR(C11/$C$15, " ") -> 0 | B11: Закрепление отзыва | C11: 0 | F11: Закрепление отзыва | I11: =IFERROR(G11/$G$15, " ") -> 0 | K11: 46030 | L11: =SUM(M11:AA11) -> 19627323 | M11: 4807368 | N11: 2446234 | O11: 6530839 | P11: 5574038 | Q11: 89892 | R11: 89707 | S11: 5707 | T11: 32069 | U11: 13711 | V11: 32468 | W11: 0 | X11: 1367 | Y11: 3923 | AC11: Золотое Яблоко | AD11: Биг–Л | AE11: =U42 -> 108947 | AG11: =AE11-AF11 -> 108947 | AI11: =U35 -> 594263 | AK11: =6497+248803 -> 255300 | AM11: =AI11-SUM(AJ11:AL11) -> 338963
B12: Иные электронные услуги | C12: 0 | F12: Иные электронные услуги | I12: =IFERROR(G12/$G$15, " ") -> 0 | K12: 46031 | L12: =SUM(M12:AA12) -> 20330202 | M12: 4572678 | N12: 2541646 | O12: 6459515 | P12: 6455582 | Q12: 160570 | R12: 75490 | S12: 2778 | T12: 25216 | U12: 11835 | V12: 23800 | W12: 0 | X12: 1092 | Y12: 0 | AD12: Смарт–Сэйл | AE12: =V42 -> 787175 | AG12: =AE12-AF12 -> 787175 | AI12: =V35 -> 954144 | AK12: =5070+101552 -> 106622 | AM12: =AI12-SUM(AJ12:AL12) -> 847522
B13: Продвижение бренда | C13: 0 | F13: Продвижение бренда | I13: =IFERROR(G13/$G$15, " ") -> 0 | K13: 46032 | L13: =SUM(M13:AA13) -> 19711678 | M13: 4112819 | N13: 2588222 | O13: 6455940 | P13: 6248328 | Q13: 143984 | R13: 80890 | S13: 852 | T13: 38289 | U13: 8440 | V13: 28341 | W13: 519 | X13: 2034 | Y13: 3020 | AD13: итог | AE13: =SUM(AE3:AE12) -> 4.1724871e+08 | AF13: =SUM(AF3:AF12) -> 0 | AG13: =SUM(AG3:AG12) -> 4.1724871e+08 | AI13: =SUM(AI3:AI12) -> 5.3871487e+08 | AJ13: =SUM(AJ3:AJ12) -> 15016926 | AK13: =SUM(AK3:AK12) -> 3135664 | AL13: =SUM(AL3:AL12) -> 0 | AM13: =SUM(AM3:AM12) -> 5.2056228e+08
B14: Ozon Рассрочка | C14: 3489 | F14: Ozon Рассрочка | K14: 46033 | L14: =SUM(M14:AA14) -> 21605574 | M14: 4530575 | N14: 2714630.1 | O14: 7582307 | P14: 6418527 | Q14: 133673 | R14: 113443 | S14: 2345 | T14: 51187 | U14: 18379 | V14: 40154 | W14: 0 | X14: 354 | Y14: 0
B15: Итого расходов | C15: =SUM(C5:C14) -> 15193291 | F15: Итого расходов | G15: =SUM(G5:G14) -> 9554433 | H15: =SUM(H5:H14) -> 0 | K15: 46034 | L15: =SUM(M15:AA15) -> 17591225 | M15: 3580582 | N15: 2588648 | O15: 6323347 | P15: 4793010 | Q15: 130482 | R15: 87713 | S15: 4132 | T15: 53349 | U15: 5913 | V15: 21940 | W15: 0 | X15: 2109 | Y15: 0
B16: Выручка | D16: =M35 -> 110647711 | F16: Выручка | H16: =N35 -> 80715472 | K16: 46035 | L16: =SUM(M16:AA16) -> 17669184 | M16: 3405536 | N16: 2677293 | O16: 6413931 | P16: 4804282 | Q16: 122025 | R16: 129246 | S16: 4559 | T16: 65581 | U16: 14141 | V16: 31532 | W16: 0 | X16: 1058 | Y16: 0
B17: ДРР / Факт | D17: =C15/D16 -> 0.13731229 | F17: ДРР / Факт | H17: =G15/H16 -> 0.11837177 | K17: 46036 | L17: =SUM(M17:AA17) -> 18073795 | M17: 3259110 | N17: 2927401 | O17: 6758846 | P17: 4620942 | Q17: 218720 | R17: 89354 | S17: 652 | T17: 39190 | U17: 131760 | V17: 27470 | W17: 0 | X17: 350 | Y17: 0 | AE17: Без вычетов | AI17: С вычетом всего
A18: =D17/C18 -> 0.66981607 | B18: ДРР / План | C18: 0.205 | D18: =D16*C18 -> 22682781 | F18: ДРР / План | G18: 0.115 | H18: =H16*G18 -> 9282279.3 | I18: =H17/G18 -> 1.0293197 | K18: 46037 | L18: =SUM(M18:AA18) -> 17661106 | M18: 3263746 | N18: 3173546.1 | O18: 6575053 | P18: 4240112 | Q18: 142817 | R18: 92858 | S18: 4989 | T18: 46946 | U18: 91475 | V18: 25202 | W18: 4362 | X18: 0 | Y18: 0 | AE18: план | AF18: выручка | AG18: дельта | AI18: реальный план | AJ18: реальная выручка | AK18: дельта
B19: Перерасход в деньгах | D19: =C15-D18 -> -7489489.8 | F19: Перераход в деньгах | H19: =G15-H18 -> 272153.66 | K19: 46038 | L19: =SUM(M19:AA19) -> 16899560 | M19: 3144609 | N19: 2930262 | O19: 6141720 | P19: 4373897 | Q19: 82701 | R19: 89159 | S19: 13252 | T19: 28135 | U19: 60952 | V19: 18068 | W19: 4951 | X19: 11854 | Y19: 0 | AC19: WB | AD19: Биг–Л | AE19: =AE3 -> 113971735 | AF19: =AI3 -> 199495328 | AG19: =IFERROR(AF19/AE19, " ") -> 1.750393 | AI19: =AG3 -> 113971735 | AJ19: =AM3 -> 198719614 | AK19: =IFERROR(AJ19/AI19, " ") -> 1.7435868
K20: 46039 | L20: =SUM(M20:AA20) -> 18037985 | M20: 3689405 | N20: 2894971 | O20: 6713211 | P20: 4378824 | Q20: 129013 | R20: 90801 | S20: 20641 | T20: 42831 | U20: 55712 | V20: 22226 | W20: 0 | X20: 350 | Y20: 0 | AD20: Смарт–Сэйл | AE20: =AE4 -> 110544589 | AF20: =AI4 -> 138055387 | AG20: =IFERROR(AF20/AE20, " ") -> 1.2488661 | AI20: =AG4 -> 110544589 | AJ20: =AM4 -> 137101317 | AK20: =IFERROR(AJ20/AI20, " ") -> 1.2402354
B21: План | D21: =M42 -> 96599698 | F21: План | H21: =N42 -> 86342890 | K21: 46040 | L21: =SUM(M21:AA21) -> 18685904 | M21: 3653633 | N21: 2944215 | O21: 7220542 | P21: 4541922 | Q21: 135656 | R21: 84878 | S21: 15716 | T21: 54000 | U21: 13200 | V21: 19972 | W21: 0 | X21: 350 | Y21: 1820 | AC21: Ozon | AD21: Биг–Л | AE21: =AE5 -> 96599698 | AF21: =AI5 -> 110647711 | AG21: =IFERROR(AF21/AE21, " ") -> 1.145425 | AI21: =AG5 -> 96599698 | AJ21: =AM5 -> 101356193 | AK21: =IFERROR(AJ21/AI21, " ") -> 1.0492392
B22: Плато продаж | D22: =D16/$C$1 -> 3569281 | F22: Плато продаж | H22: =H16/$C$1 -> 2603724.9 | K22: 46041 | L22: =SUM(M22:AA22) -> 15737815 | M22: 3019828 | N22: 2676091 | O22: 6463237 | P22: 3278254 | Q22: 108977 | R22: 91125 | S22: 13229 | T22: 32886 | U22: 10429 | V22: 21021 | W22: 4951 | X22: 12856 | Y22: =3260+1671 -> 4931 | AD22: Смарт–Сэйл | AE22: =AE6 -> 86342890 | AF22: =AI6 -> 80715472 | AG22: =IFERROR(AF22/AE22, " ") -> 0.93482478 | AI22: =AG6 -> 86342890 | AJ22: =AM6 -> 74707614 | AK22: =IFERROR(AJ22/AI22, " ") -> 0.86524339
B23: Нужно сделать на вчера | D23: =D21/$G$1*$C$1 -> 96599698 | F23: Нужно сделать на вчера | H23: =H21/$G$1*$C$1 -> 86342890 | K23: 46042 | L23: =SUM(M23:AA23) -> 16806629 | M23: 3319665 | N23: 2624808.1 | O23: 7008494 | P23: 3568647 | Q23: 116701 | R23: 89586 | S23: 12058 | T23: 36967 | U23: 7030 | V23: 18125 | W23: 0 | X23: 625 | Y23: 3923 | AC23: ЯМаркет | AD23: Биг–Л | AE23: =AE7 -> 3741104 | AF23: =AI7 -> 3639698 | AG23: =IFERROR(AF23/AE23, " ") -> 0.9728941 | AI23: =AG7 -> 3741104 | AJ23: =AM7 -> 3150063.3 | AK23: =IFERROR(AJ23/AI23, " ") -> 0.84201437
B24: Нужно делать в день | D24: =(D21-D16)/($G$1-$C$1) -> #DIV/0! | F24: Нужно делать в день | H24: =(H21-H16)/($G$1-$C$1) -> #DIV/0! | K24: 46043 | L24: =SUM(M24:AA24) -> 16307741 | M24: 3428781 | N24: 2824083 | O24: 6595730 | P24: 3178278 | Q24: 98397 | R24: 101178 | S24: 21004 | T24: 33265 | U24: 7567 | V24: 13033 | W24: 0 | X24: 963 | Y24: 5462 | AD24: Смарт–Сэйл | AE24: =AE8 -> 3478652 | AF24: =AI8 -> 2771328 | AG24: =IFERROR(AF24/AE24, " ") -> 0.79666721 | AI24: =AG8 -> 3478652 | AJ24: =AM8 -> 2508567.8 | AK24: =IFERROR(AJ24/AI24, " ") -> 0.72113214
B25: Дельта от плана | D25: =D16-D23 -> 14048013 | F25: Дельта от плана | H25: =H16-H23 -> -5627417 | K25: 46044 | L25: =SUM(M25:AA25) -> 15948570 | M25: 3208929 | N25: 2682373 | O25: 6712160 | P25: 3081188 | Q25: 81765 | R25: 102694 | S25: 13929 | T25: 31414 | U25: 5837 | V25: 18559 | W25: 0 | X25: 412 | Y25: 9310 | AC25: Летуаль | AD25: Биг–Л | AE25: =AE9 -> 341575 | AF25: =AI9 -> 355446 | AG25: =IFERROR(AF25/AE25, " ") -> 1.0406089 | AI25: =AG9 -> 341575 | AJ25: =AM9 -> 355446 | AK25: =IFERROR(AJ25/AI25, " ") -> 1.0406089
B26: Прогноз по выручке | D26: =D16/$C$1*$G$1 -> 110647711 | F26: Прогноз по выручке | H26: =H16/$C$1*$G$1 -> 80715472 | K26: 46045 | L26: =SUM(M26:AA26) -> 16037350 | M26: 3114310 | N26: 2489130 | O26: 6691021 | P26: 3428916 | Q26: 100361 | R26: 118655 | S26: 26964 | T26: 35129 | U26: 6793 | V26: 23951 | W26: 0 | X26: 2119.6 | Y26: 0 | AD26: Смарт–Сэйл | AE26: =AE10 -> 1332348 | AF26: =AI10 -> 1486093 | AG26: =IFERROR(AF26/AE26, " ") -> 1.115394 | AI26: =AG10 -> 1332348 | AJ26: =AM10 -> 1476980 | AK26: =IFERROR(AJ26/AI26, " ") -> 1.1085542
B27: Прогноз по выручке (%) | D27: =D26/D21 -> 1.145425 | F27: Прогноз по выручке (%) | H27: =H26/H21 -> 0.93482478 | K27: 46046 | L27: =SUM(M27:AA27) -> 17236473 | M27: 3218517 | N27: 2311041 | O27: 7087777 | P27: 4363050 | Q27: 81270 | R27: 82784 | S27: 15162 | T27: 50584 | U27: 0 | V27: 22682 | W27: 0 | X27: 1934.72 | Y27: 1671 | AC27: Золотое Яблоко | AD27: Биг–Л | AE27: =AE11 -> 108947 | AF27: =AI11 -> 594263 | AG27: =IFERROR(AF27/AE27, " ") -> 5.4546064 | AI27: =AG11 -> 108947 | AJ27: =AM11 -> 338963 | AK27: =IFERROR(AJ27/AI27, " ") -> 3.1112651
K28: 46047 | L28: =SUM(M28:AA28) -> 18387426 | M28: 3209513 | N28: 2556223 | O28: 8207164 | P28: 4081725 | Q28: 134816 | R28: 89292 | S28: 21601 | T28: 51382 | U28: 14338 | V28: 19152 | W28: 1721.5 | X28: 499 | AD28: Смарт–Сэйл | AE28: =AE12 -> 787175 | AF28: =AI12 -> 954144 | AG28: =IFERROR(AF28/AE28, " ") -> 1.2121117 | AI28: =AG12 -> 787175 | AJ28: =AM12 -> 847522 | AK28: =IFERROR(AJ28/AI28, " ") -> 1.0766627
B29: Wildberries / Расход бонусы + рубли | K29: 46048 | L29: =SUM(M29:AA29) -> 17262930 | M29: 2821820 | N29: 2460326 | O29: 7796368 | P29: 3864302 | Q29: 132330 | R29: 79854 | S29: 17500 | T29: 65196 | U29: 12731 | V29: 11897 | W29: 0 | X29: 606 | AE29: =SUM(AE19:AE28) -> 4.1724871e+08 | AF29: =SUM(AF19:AF28) -> 5.3871487e+08 | AG29: =IFERROR(AF29/AE29, " ") -> 1.2911121 | AI29: =SUM(AI19:AI24) -> 4.1467867e+08 | AJ29: =SUM(AJ19:AJ24) -> 5.1754337e+08 | AK29: =IFERROR(AJ29/AI29, " ") -> 1.2480588
B30: =B4 -> Биг–Л / Январь | до | D30: =$D$4 -> 46053 | F30: =F4 -> Смарт/ Январь| до | H30: =$D$4 -> 46053 | K30: 46049 | L30: =SUM(M30:AA30) -> 17041905 | M30: 2794855 | N30: 3064152.1 | O30: 6673030 | P30: 4242575 | Q30: 109414 | R30: 78086 | S30: 17404 | T30: 41577 | U30: 10202 | V30: 9903 | W30: 0 | X30: 707
A31: =IFERROR(C31/$C$33, " ") -> 0.7738597 | B31: Затраты из РК | C31: 7405850 | F31: Затраты из РК | G31: 5522659 | I31: =IFERROR(G31/$G$33, " ") -> 0.97238956 | K31: 46050 | L31: =SUM(M31:AA31) -> 17583543 | M31: 3017452 | N31: 2834095 | O31: 6280295 | P31: 5172583 | Q31: 101257 | R31: 77444 | S31: 16060 | T31: 58970 | U31: 11046 | V31: 13929 | W31: 0 | X31: 412 | AC31: Только рубли | AE31: реальная выручка | AF31: реклама | AG31: ДРР | AI31: ДРР план | AJ31: ДРР факт | AK31: дельта
A32: =IFERROR(C32/$C$33, " ") -> 0.2261403 | B32: Отзывы за баллы | C32: 2164166.4 | F32: Отзывы за баллы | G32: 156812.7 | I32: =IFERROR(G32/$G$33, " ") -> 0.027610438 | K32: 46051 | L32: =SUM(M32:AA32) -> 19036655 | M32: 3497809 | N32: 3194764 | O32: 6253583 | P32: 5723933 | Q32: 102004 | R32: 98401 | S32: 12647 | T32: 49844 | U32: 14099 | V32: 88643 | W32: 0 | X32: 928.2 | AC32: WB | AD32: Биг–Л | AE32: =AM3 -> 198719614 | AF32: =C51 -> 4572564 | AG32: =AF32/AE32 -> 0.023010129 | AH32: =AE32/(AE32+AE33) -> 0.59174279 | AI32: =C36 -> 0.07 | AJ32: =AG32 -> 0.023010129 | AK32: =AJ32/AI32-1 -> -0.67128387
B33: Итого расходов | C33: =SUM(C31:C32) -> 9570016.4 | F33: Итого расходов | G33: =SUM(G31:G32) -> 5679471.7 | K33: 46052 | L33: =SUM(M33:AA33) -> 18776797 | M33: 3753135 | N33: 2542336 | O33: 6120832 | P33: 5913138 | Q33: 76364 | R33: 81417 | S33: 59578 | T33: 159684 | U33: 2950 | V33: 64373 | W33: 0 | X33: 2990 | AD33: Смарт–Сэйл | AE33: =AM4 -> 137101317 | AF33: =G51 -> 3391496 | AG33: =AF33/AE33 -> 0.024737151 | AH33: =AE33/(AE33+AE34) -> 0.57495072 | AI33: =G36 -> 0.07 | AJ33: =AG33 -> 0.024737151 | AK33: =AJ33/AI33-1 -> -0.64661213
B34: Выручка | D34: =O35 -> 199495328 | E34: 73474830 | F34: Выручка | H34: =P35 -> 138055387 | J34: =I35/H34 -> 0.14354939 | K34: 46053 | L34: =SUM(M34:AA34) -> 20892450 | M34: 4101445 | N34: 2740713 | O34: 7285573 | P34: 6365044 | Q34: 124548 | R34: 93494 | S34: 17076 | T34: 76743 | U34: 14257 | V34: 73066 | W34: 0 | X34: 491 | AC34: Ozon | AD34: Биг–Л | AE34: =AM5 -> 101356193 | AF34: =C15 -> 15193291 | AG34: =AF34/AE34 -> 0.14989998 | AH34: =AE34/(AE34+AE35) -> 0.57567875 | AI34: =C18 -> 0.205 | AJ34: =AG34 -> 0.14989998 | AK34: =AJ34/AI34-1 -> -0.2687806
B35: ДРР / Факт | D35: =C33/D34 -> 0.04797113 | E35: =E34/D34 -> 0.36830351 | F35: ДРР / Факт | H35: =G33/H34 -> 0.041139081 | I35: 19817766 | K35: =L35/C1 -> 17381378 | L35: =SUM(L4:L34) -> 5.3882271e+08 | M35: =SUM(M4:M34) -> 110647711 | N35: =SUM(N4:N34) -> 80715472 | O35: =SUM(O4:O34) -> 199495328 | P35: =SUM(P4:P34) -> 138055387 | Q35: =SUM(Q4:Q34) -> 3639698 | R35: =SUM(R4:R34) -> 2771328 | S35: =SUM(S4:S34) -> 355446 | ... AA35: =SUM(AA4:AA34) -> 0 | AD35: Смарт–Сэйл | AE35: =AM6 -> 74707614 | AF35: =G15 -> 9554433 | AG35: =AF35/AE35 -> 0.12789102 | AH35: =AE35/(AE35+AE36) -> 0.95954075 | AI35: =G18 -> 0.115 | AJ35: =AG35 -> 0.12789102 | AK35: =AJ35/AI35-1 -> 0.11209583
A36: =D35/C36 -> 0.68530186 | B36: ДРР / План | C36: 0.07 | D36: =D34*C36 -> 13964673 | E36: 73 474 830 | F36: ДРР / План | G36: 0.07 | H36: =H34*G36 -> 9663877.1 | I36: =H35/G36 -> 0.58770115 | M36: =M35/$L$35 -> 0.20535087 | N36: =N35/$L$35 -> 0.14979969 | O36: =O35/$L$35 -> 0.37024299 | P36: =P35/$L$35 -> 0.25621672 | Q36: =Q35/$L$35 -> 0.0067549083 | R36: =R35/$L$35 -> 0.0051433022 | S36: =S35/$L$35 -> 0.00065967153 | T36: =T35/$L$35 -> 0.0027580371 | ... AA36: =AA35/$L$35 -> 0 | AC36: ЯМаркет | AD36: Биг–Л | AE36: =AM7 -> 3150063.3 | AF36: =C72 -> 461196 | AG36: =AF36/AE36 -> 0.14640848 | AH36: =AE36/(AE36+AE37) -> 0.55668293 | AI36: =C75 -> 0.18 | AJ36: =AG36 -> 0.14640848 | AK36: =AJ36/AI36-1 -> -0.18661953
B37: Перераход в деньгах | D37: =C33-D36 -> -4394656.6 | F37: Перераход в деньгах | H37: =G33-H36 -> -3984405.4 | AD37: Смарт–Сэйл | AE37: =AM8 -> 2508567.8 | AF37: =G72 -> 482427 | AG37: =AF37/AE37 -> 0.19231173 | AH37: =AE37/(AE37+AE38) -> 0.87589236 | AI37: =G75 -> 0.175 | AJ37: =AG37 -> 0.19231173 | AK37: =AJ37/AI37-1 -> 0.09892416
K38: Распределение по направлениям | M38: =SUM(M40:N40)/$L$40 -> 0.35515055 | O38: =SUM(O40:P40)/$L$40 -> 0.62645971 | Q38: =SUM(Q40:R40)/$L$40 -> 0.01189821 | S38: =SUM(S40:T40)/$L$40 -> 0.0034177086 | U38: =SUM(U40:V40)/$L$40 -> 0.0028736855 | W38: =SUM(W40:X40)/$L$40 -> 0.00013187458 | Y38: =SUM(Y40:Z40)/$L$40 -> 6.8261785e-05 | AC38: Летуаль | AD38: Биг–Л | AE38: =AM9 -> 355446 | AF38: 0 | AG38: =AF38/AE38 -> 0 | AH38: =AE38/(AE38+AE39) -> 0.19397564 | AI38: =C91 -> 0.15 | AJ38: =AG38 -> 0 | AK38: =AJ38/AI38-1 -> -1
B39: План | D39: =O42 -> 113971735 | F39: План | H39: =P42 -> 110544589 | K39: Распределение продаж | L39: =L40/$L$40 -> 1 | M39: =M40/$L$40 -> 0.20535087 | N39: =N40/$L$40 -> 0.14979969 | O39: =O40/$L$40 -> 0.37024299 | P39: =P40/$L$40 -> 0.25621672 | Q39: =Q40/$L$40 -> 0.0067549083 | R39: =R40/$L$40 -> 0.0051433022 | S39: =S40/$L$40 -> 0.00065967153 | ... AA39: =AA40/$L$40 -> 0 | AD39: Смарт–Сэйл | AE39: =AM10 -> 1476980 | AF39: 0 | AG39: =AF39/AE39 -> 0 | AH39: =AE39/(AE39+AE40) -> 0.81334051 | AI39: =G91 -> 0.15 | AJ39: =AG39 -> 0 | AK39: =AJ39/AI39-1 -> -1
B40: Плато продаж | D40: =D34/$C$1 -> 6435333.2 | F40: Плато продаж | H40: =H34/$C$1 -> 4453399.6 | K40: Прогноз | L40: =L35/$C$1*$G$1 -> 5.3882271e+08 | M40: =M35/$C$1*$G$1 -> 110647711 | N40: =N35/$C$1*$G$1 -> 80715472 | O40: =O35/$C$1*$G$1 -> 199495328 | P40: =P35/$C$1*$G$1 -> 138055387 | Q40: =Q35/$C$1*$G$1 -> 3639698 | R40: =R35/$C$1*$G$1 -> 2771328 | S40: =S35/$C$1*$G$1 -> 355446 | ... AA40: =AA35/$C$1*$G$1 -> 0 | AC40: Золотое Яблоко | AD40: Биг–Л | AE40: =AM11 -> 338963 | AF40: 0 | AG40: =AF40/AE40 -> 0 | AH40: =AE40/(AE40+AE41) -> 0.28568671 | AI40: 0 | AJ40: =AG40 -> 0 | AK40: =AJ40/AI40-1 -> #DIV/0!
...

Sheet Декабрь 25
A1: 3 | B1: Вчера | C1: 31 | F1: Дней в месяце | G1: 31
A2: Актуально на | B2: 46022 | M2: Оз | O2: Вб | Q2: Ям | S2: Лету | U2: ЗЯ | W2: Магнит Маркет | AB2: план | AC2: ауты | AD2: реальный план | AF2: выручка | AG2: отказы/возвраты | AH2: раздачи | AI2: выкупы | AJ2: реальная выручка
B3: Ozon | M3: Биг–Л | N3: Смарт | O3: Биг–Л | P3: Смарт | Q3: Биг–Л | R3: Смарт | S3: Биг–Л | T3: Смарт | U3: Биг–Л | V3: Смарт | W3: Биг–Л | X3: Смарт | Z3: WB | AA3: Биг–Л | AB3: =D39 -> 103370590 | AD3: =AB3-AC3 -> 103370590 | AF3: =O35 -> 113971735 | AH3: =1800+263901 -> 265701 | AJ3: =AF3-SUM(AG3:AI3) -> 113706034
B4: Биг–Л / Ноябрь | до | D4: =TODAY()-1 -> 46107 | F4: Смарт / Декабрь| до | H4: =$D$4 -> 46107 | K4: 45992 | L4: =SUM(M4:X4) -> 12621391 | M4: 2348963 | N4: 2898929.1 | O4: 3616967 | P4: 3509563 | Q4: 65103 | R4: 91393 | S4: 17685 | T4: 60837 | V4: 11951 | W4: 0 | X4: 0 | AA4: Смарт–Сэйл | AB4: =H39 -> 124247057 | AD4: =AB4-AC4 -> 124247057 | AF4: =P35 -> 110544589 | AH4: =28907+1322280 -> 1351187 | AJ4: =AF4-SUM(AG4:AI4) -> 109193402
A5: =IFERROR(C5/$C$15, " ") -> 0.9209805 | B5: Оплата за клик | C5: 11804615 | F5: Оплата за клик | G5: 10022821 | H5: 368630 | I5: =IFERROR(G5/$G$15, " ") -> 0.91460396 | K5: 45993 | L5: =SUM(M5:X5) -> 12055242 | M5: 2720347 | N5: 2750788 | O5: 3361085 | P5: 2870498 | Q5: 114964 | R5: 140722 | S5: 19993 | T5: 69540 | V5: 6491 | W5: 0 | X5: 814.4 | Z5: Ozon | AA5: Биг–Л | AB5: =D21 -> 68328978 | AD5: =AB5-AC5 -> 68328978 | AF5: =M35 -> 96599698 | AG5: =AF5/79355*(6496+66) -> 7987993.4 | AH5: =17128+715194 -> 732322 | AJ5: =AF5-SUM(AG5:AI5) -> 87879383
A6: =IFERROR(C6/$C$15, " ") -> 0.052100485 | B6: Оплата за заказ | C6: 667795 | F6: Оплата за заказ | G6: 555930 | H6: 3064 | I6: =IFERROR(G6/$G$15, " ") -> 0.050729807 | K6: 45994 | L6: =SUM(M6:X6) -> 14114630 | M6: 3028089 | N6: 3048715.1 | O6: 3986511 | P6: 3745955 | Q6: 90370 | R6: 152662 | S6: 9962 | T6: 41817 | V6: 10549 | W6: 0 | X6: 0 | AA6: Смарт–Сэйл | AB6: =H21 -> 73964393 | AD6: =AB6-AC6 -> 73964393 | AF6: =N35 -> 86342890 | AG6: =AF6/85340*(5785+94) -> 5948088.2 | AH6: =516107 -> 516107 | AJ6: =AF6-SUM(AG6:AI6) -> 79878694
A7: =IFERROR(C7/$C$15, " ") -> 0.013733004 | B7: Медийка | C7: 176022 | F7: Медийка | G7: 199419 | H7: 9571 | I7: =IFERROR(G7/$G$15, " ") -> 0.018197412 | K7: 45995 | L7: =SUM(M7:X7) -> 13301924 | M7: 2696101 | N7: 3017920.1 | O7: 3627559 | P7: 3646639 | Q7: 111668 | R7: 134129 | S7: 12162 | T7: 40785 | V7: 14146 | W7: 0 | X7: 814.4 | Z7: ЯМаркет | AA7: Биг–Л | AB7: =D78 -> 2491703 | AD7: =AB7-AC7 -> 2491703 | AF7: =Q35 -> 3741104 | AG7: =AF7/4436*354 -> 298546.17 | AH7: 83542 | AJ7: =AF7-SUM(AG7:AI7) -> 3359015.8
A8: =IFERROR(C8/$C$15, " ") -> 0.00033142336 | B8: Баллы за отзывы | C8: 4248 | F8: Баллы за отзывы | G8: 4541 | H8: 504 | I8: =IFERROR(G8/$G$15, " ") -> 0.00041437601 | K8: 45996 | L8: =SUM(M8:X8) -> 13344410 | M8: 3005335 | N8: 2928242 | O8: 3832361 | P8: 3269890 | Q8: 108809 | R8: 130447 | S8: 11076 | T8: 43974 | V8: 14276 | W8: 0 | X8: 0 | AA8: Смарт–Сэйл | AB8: =H78 -> 4455445 | AD8: =AB8-AC8 -> 4455445 | AF8: =R35 -> 3478652 | AG8: =AF8/5096*344 -> 234822.66 | AH8: 52926 | AJ8: =AF8-SUM(AG8:AI8) -> 3190903.3
A9: =IFERROR(C9/$C$15, " ") -> 0.012683965 | B9: Бонусы продавца | C9: 162576 | F9: Бонусы продавца | G9: 163324 | H9: 5649 | I9: =IFERROR(G9/$G$15, " ") -> 0.014903666 | K9: 45997 | L9: =SUM(M9:X9) -> 14034429 | M9: 3192032 | N9: 3059169 | O9: 3592132 | P9: 3862451 | Q9: 122857 | R9: 144391 | S9: 9170 | T9: 37926 | V9: 14301 | W9: 0 | X9: 0 | Z9: Летуаль | AA9: Биг–Л | AB9: =S42 -> 357438 | AD9: =AB9-AC9 -> 357438 | AF9: =S35 -> 341575 | AH9: =1200+12302 -> 13502 | AJ9: =AF9-SUM(AG9:AI9) -> 328073
A10: =IFERROR(C10/$C$15, " ") -> 0 | B10: Рассылки | C10: 0 | F10: Рассылки | G10: 12611 | H10: 0 | I10: =IFERROR(G10/$G$15, " ") -> 0.0011507809 | K10: 45998 | L10: =SUM(M10:X10) -> 15208375 | M10: 3067649 | N10: 3149598.2 | O10: 4283439 | P10: 4303678 | Q10: 132807 | R10: 163980 | S10: 15530 | T10: 67339 | V10: 24355 | W10: 0 | X10: 0 | AA10: Смарт–Сэйл | AB10: =T42 -> 1099783 | AD10: =AB10-AC10 -> 1099783 | AF10: =T35 -> 1332348 | AH10: =49831 -> 49831 | AJ10: =AF10-SUM(AG10:AI10) -> 1282517
A11: =IFERROR(C11/$C$15, " ") -> 0 | B11: Закрепление отзыва | C11: 0 | F11: Закрепление отзыва | H11: 0 | I11: =IFERROR(G11/$G$15, " ") -> 0 | K11: 45999 | L11: =SUM(M11:X11) -> 13657181 | M11: 3122113 | N11: 2979476 | O11: 3936946 | P11: 3228434 | Q11: 152478 | R11: 117561 | S11: 12620 | T11: 80627 | V11: 26112 | W11: 0 | X11: 814.4 | Z11: Золотое Яблоко | AA11: Биг–Л | AB11: =U42 -> 0 | AD11: =AB11-AC11 -> 0 | AF11: =U35 -> 108947 | AH11: =34498 -> 34498 | AJ11: =AF11-SUM(AG11:AI11) -> 74449
B12: Иные электронные услуги | C12: 0 | F12: Иные электронные услуги | H12: 0 | I12: =IFERROR(G12/$G$15, " ") -> 0 | K12: 46000 | L12: =SUM(M12:X12) -> 13488241 | M12: 2980974 | N12: 3079510.1 | O12: 3805093 | P12: 3318450 | Q12: 123931 | R12: 103883 | S12: 8340 | T12: 34905 | V12: 28886 | W12: 0 | X12: 4268.8 | AA12: Смарт–Сэйл | AB12: =V42 -> 1079042 | AD12: =AB12-AC12 -> 1079042 | AF12: =V35 -> 787175 | AH12: =76776 -> 76776 | AJ12: =AF12-SUM(AG12:AI12) -> 710399
