Workbook

Sheet Инфо по SKU
A1: А пон | D1: Андрей Л | E1: Андрей Л | F1: Вячеслав | G1: Продукты | H1: Продукты | K1: Вячеслав | L1: Анна З | M1: Анна З | N1: Анна З | O1: Анна З | P1: Анна З | Q1: Анна З | S1: Вячеслав | T1: Анна З | U1: Анна З | V1: Анна З | W1: Анна З | X1: Анна З | Y1: Анна З | AA1: Анна З | AB1: Анна З | AC1: Анна З | AD1: Анна З | AE1: Анна З | AF1: Анна З | AH1: Вячеслав | AI1: Маркетолог по МП | AJ1: Маркетолог по МП | AK1: Маркетолог по МП | AL1: Маркетолог по МП | AM1: Маркетолог по МП | AN1: Маркетолог по МП | AP1: Анна З | AQ1: Анна З | AR1: Анна З | AS1: Анна З | AT1: Анна З | AU1: Анна З | AW1: Маркетолог по МП | AX1: Маркетолог по МП | AY1: Маркетолог по МП | AZ1: Маркетолог по МП | BA1: Маркетолог по МП | BB1: Маркетолог по МП | BJ1: @dropdown | BL1: Продуктологи | BM1: Продуктологи | BN1: Продуктологи | BO1: Продуктологи | BP1: Продуктологи | BS1: Продуктологи | BT1: Аня З / Продуктологи | BU1: Продуктологи | BV1: Продуктологи | BW1: Продуктологи | BX1: Продуктологи | BY1: Продуктологи | BZ1: Продуктологи | CB1: Продуктологи | CC1: Продуктологи | CF1: Продуктологи / Аня З | CG1: Аня Клименко | CH1: Александра З | CI1: Александра З | CJ1: Александра З | CM1: Автоматом / Таблица инвентаризация себеса | CZ1: Маркетинг + Продукты | DA1: Маркетинг + Продукты | DB1: Маркетинг + Продукты | DC1: Александра З | DD1: Маркетинг + Продукты | DE1: Маркетинг + Продукты | DF1: Маркетинг + Продукты | DG1: Леша В | DH1: Леша В | DI1: Леша В | DJ1: Продукты + Леша В | DK1: Продукты + Леша В | DL1: Продукты + Леша В | DM1: Продукты + Леша В | DN1: Продукты + Леша В | DO1: Леша В | DP1: Леша В | DQ1: Леша В | DR1: Леша В | DS1: Леша В | DT1: Леша В | DU1: Леша В | DV1: Леша В | DW1: Леша В | DX1: Леша В | DY1: Леша В | DZ1: Леша В | EA1: Леша В | EB1: Леша В | EC1: Леша В | ED1: Леша В | EE1: Леша В | EF1: Леша В | EG1: Леша В | EH1: Леша В | EI1: Леша В | EJ1: Леша В | EK1: Леша В | EL1: Леша В | EM1: Леша В | EN1: Леша В | EO1: Леша В | EP1: Леша В | EQ1: Леша В | ER1: Леша В | ES1: Продукты + Леша В | ET1: Продукты + Леша В | EU1: Продукты + Леша В | EV1: Продукты + Леша В | EW1: Продукты + Леша В | EX1: Продукты + Леша В | EY1: Продукты + Леша В | EZ1: Продукты + Леша В | FA1: Продукты + Леша В | FB1: Продукты + Леша В | FC1: Продукты + Леша В | FD1: Продукты + Леша В | FE1: Продукты + Леша В | FF1: Продукты + Леша В | FG1: Продукты + Леша В | FH1: Продукты + Леша В
I2: Идентификация товаров | J2: Товар заведен | R2: SKU МП + 1С | Z2: Артикула МП | AG2: Наименования МП + 1С | AO2: Ссылки на товар | AV2: Категория товара на МП | BC2: Ответственные по МП | BK2: Документы и маркировка | BR2: Характеристики продукта | CE2: Макет / Дизайн / Этикетка | CL2: Производственный блок | CX2: Габариты товара & Логистический блок | DO2: new | DP2: new | DQ2: new | DR2: new | DS2: new | DT2: new | DU2: new | DV2: new | DW2: new | DX2: new | DY2: new | DZ2: new | EA2: new | EB2: new | EC2: new | ED2: new | EE2: new | EF2: new | EG2: new | EH2: new | EI2: new | EJ2: new | EK2: new | EL2: new | EM2: new | EN2: new | EO2: new | EP2: new | EQ2: new | ER2: new | ES2: будет заполняться постепенно
G3: Перепроверить / Влад / Сходится ли с 1с | AH3: копия столбца G | BO3: Аня З | BW3: спецификация | CA3: спецификация | CF3: спецификация | CM3: Инвентаризация себестоимости МП май 2024 | CZ3: new | DA3: new | DB3: new | DD3: new | DE3: new | DF3: new | DG3: Таблица от Вики | DO3: Габариты единицы товара с упаковкой | ES3: данных нет | ET3: данных нет | EU3: данных нет | EV3: данных нет | EW3: данных нет | EX3: данных нет | EY3: данных нет | EZ3: данных нет | FA3: данных нет | FB3: данных нет | FC3: данных нет | FD3: данных нет | FE3: данных нет | FF3: данных нет | FG3: данных нет | FH3: данных нет
D4: Актуальность товара | F4: Блок 1С | G4: Категории внутреннего распределения | BO4: kma.biz | BT4: new составы меняются | BU4: Рекомендации по применению Переименовываем | BY4: new | BZ4: Уточнить у Саши что имела ввиду | CA4: new | CG4: new | CI4: new | CJ4: new | CM4: Формулой | CO4: продукты | CR4: new | CS4: new | CT4: new | CU4: new | CV4: new | CY4: Файл от Вики / чат | CZ4: Необходимость доп упаковки | DD4: Требования МП по упаковке | DG4: Вид расходника | DJ4: Штука | DO4: Ozon | DT4: WB | DY4: YM | ED4: Лету | EI4: ЗЯ | EN4: Магнит Маркет | ES4: Блок – Смотка | EX4: Короб | FC4: Паллет
A5: Направление | B5: SKU | C5: Бренд | D5: Статус товара | E5: Комментарий | F5: Полное наименование | G5: Категория 1 | H5: Категория 2 | K5: 1С | L5: WB | M5: Ozon | N5: ЯМаркет | O5: Золотое Яблоко | P5: Летуаль | Q5: Магнит Маркет | S5: 1С | T5: WB | U5: Ozon | V5: ЯМаркет | W5: Золотое Яблоко | X5: Летуаль | Y5: Магнит Маркет | AA5: WB | AB5: Ozon | AC5: ЯМаркет | AD5: Золотое Яблоко | AE5: Летуаль | AF5: Магнит Маркет | AH5: 1С | AI5: WB | AJ5: Ozon | AK5: ЯМаркет | AL5: Золотое Яблоко | AM5: Летуаль | AN5: Магнит Маркет | AP5: WB | AQ5: Ozon | AR5: ЯМаркет | AS5: Золотое Яблоко | AT5: Летуаль | AU5: Магнит Маркет | AW5: WB | AX5: Ozon | AY5: ЯМаркет | AZ5: Золотое Яблоко | BA5: Летуаль | BB5: Магнит Маркет | BD5: WB | BE5: Ozon | BF5: ЯМаркет | BG5: Золотое Яблоко | BH5: Летуаль | BI5: Магнит Маркет | BL5: ШК | BM5: ТНВЭД | BN5: Документы качества | BO5: Ссылка на документы | BP5: Маркировка | BS5: Состав | BT5: Дата изменения состава | BU5: Применение | BV5: Противопоказания | BW5: Хранение | BX5: Количество | BY5: Форма выпуска | BZ5: Масса капсулы / таблетки | CA5: Срок годности на этикетке | CB5: Срок годности для нас | CC5: Продакт файл | CF5: Этикетка | CG5: Дата изменения | CH5: Этикетка (+ коробка) | CI5: Мокап | CJ5: Креативы | CM5: Себестоимость | CN5: Производитель | CO5: Альтернативный производитель | CP5: Контакты производителя | CQ5: Срок производства | CR5: Адрес производства | CS5: Срок доставки до нашего склада | CT5: Возможность отправлять прямо на МП | CU5: Типография этикетки | CV5: Контакт типографии | CY5: Необходимость доупаковки товара | CZ5: Oz | DA5: Wb | DB5: YM | DC5: Этикетка для склада | DD5: Oz | DE5: Wb | DF5: YM | DG5: Oz | DH5: Wb | DI5: YM | DJ5: Высота | DK5: Ширина | DL5: Глубина | DM5: Объем | DN5: Вес | DO5: Высота | DP5: Ширина | DQ5: Глубина | DR5: Объем | DS5: Вес | DT5: Высота | DU5: Ширина | DV5: Глубина | DW5: Объем | DX5: Вес | DY5: Высота | DZ5: Ширина | EA5: Глубина | EB5: Объем | EC5: Вес | ED5: Высота | EE5: Ширина | EF5: Глубина | EG5: Объем | EH5: Вес | EI5: Высота | EJ5: Ширина | EK5: Глубина | EL5: Объем | EM5: Вес | EN5: Высота | EO5: Ширина | EP5: Глубина | EQ5: Объем | ER5: Вес | ES5: Высота | ET5: Ширина | EU5: Глубина | EV5: Объем | EW5: Вес | EX5: Высота | EY5: Ширина | EZ5: Глубина | FA5: Объем | FB5: Количество | FC5: Высота | FD5: Ширина | FE5: Гоубина | FF5: Объем | FG5: Количество | FH5: Кратность коробов к ряду
A6: Биг-Л | B6: harly_paste_75ml_v2 | C6: Harly | D6: Актуальный | F6: Паста для вывода шерсти кошек ,Harly, 75 мл | G6: Корма и Кормовые добавки | H6: Витамины для кошек | K6: TRUE | L6: TRUE | M6: TRUE | N6: FALSE | O6: FALSE | P6: FALSE | Q6: FALSE | S6: HB101100407 | T6: harly_paste_75ml_v2 | U6: harly_paste_75ml_v2 | AA6: 473683865 | AB6: 2517120405 | AH6: Паста для вывода шерсти кошек ,Harly, 75 мл | AI6: Паста для вывода шерсти кошек и хорьков 75 мл | AJ6: Паста для вывода шерсти кошек и хорьков Harly 75 мл | AP6: https://www.wildberries.ru/catalog/473683865/detail.aspx | AQ6: https://www.ozon.ru/product/2517120405 | AW6: Пасты для животных | AX6: Паста для вывода шерсти кошек и хорьков Harly 75 мл | BD6: Алексей | BE6: Кристина | BF6: Анна Пирогова | BG6: Екатерина Доможирова | BH6: Екатерина Доможирова | BI6: Екатерина Доможирова | BL6: 4605543013096 | BM6: 2309909609 | BN6: ДС | BO6: https://drive.google.com/drive/folders/1PqXUMTMlCs1-1shAXBWFmXZz1thQTrG7 | BP6: меркурий, ЧЗ | BS6: масло растительное пищевое, гидролизат белковый, жир растительный, стабилизатор, экстракт солода, масло клещевины, волокна растительные пищевые, масло вазелиновое, лецитин соевый, экстракт кошачьей мяты, антиоксидант, консервант. | BU6: давать один раз в день до кормления или добавлять в корм: кошкам массой более 2 кг - 5 см пасты; кошкам массой до 2 кг, котятам, хорькам - 2 см пасты. В период линьки порцию можно увеличить вдвое. | BW6: Хранить в течение 12 месяцев при температуре от 0 до 25 ℃. Вскрытую упаковку рекомендуется хранить в холодильнике. | BX6: 75 | BY6: мл | CA6: 12 месяцев | CB6: 12 месяцев | CC6: https://docs.google.com/document/d/1XPxvc0_rnwY-m_Fi8Z3tguz_Y9D15h6gupsd_lqR5Tk/edit | CG6: 46083 | CH6: https://disk.yandex.ru/d/5CofSvNzSJz4RA | CM6: =IFERROR(VLOOKUP(B6,CC!A:D,4,0)," ") -> 145.43 | CN6: ООО "ВЕДА" | CP6: "Дмитрий Алексеев / Dmitry Alekseev Коммерческий директор ООО ""ВЕДА Вет-Фарм"" / Commercial Director VEDA Vet-Farm +7-919-766-6452 dmitriy.alexeev@vedaved.ru " | CQ6: 30 | CS6: 1 | CT6: нет | CY6: FALSE | CZ6: FALSE | DA6: FALSE | DB6: FALSE | DC6: ссылка на папку | DG6: Короб | DJ6: 5 | DK6: 15 | DL6: 5 | DM6: 375 | DN6: 0.092
A7: Биг-Л | B7: Harly_cat_support_100tabs | C7: Harly | D7: Актуальный | F7: Витамины для кастрированных котов, Harly, 100 таблеток | G7: Корма и Кормовые добавки | H7: Витамины для кошек | K7: TRUE | L7: TRUE | M7: TRUE | N7: TRUE | O7: FALSE | P7: FALSE | Q7: FALSE | S7: HB101100400 | T7: Harly_cat_support_100tabs | U7: Harly_cat_support_100tabs | V7: Harly_cat_support_100tabs | AA7: 163683380 | AB7: 1010948247 | AC7: 102632683755 | AH7: Витамины для кастрированных котов, Harly, 100 таблеток | AI7: Витамины для кастрированных и стерилизованных кошек | AJ7: Витамины для кастрированных и стерилизованных котов, 100 таблеток | AK7: Витамины для кошек кастрированных и стерилизованных котов, 100 таблеток | AP7: https://www.wildberries.ru/catalog/163683380/detail.aspx | AQ7: https://www.ozon.ru/product/1010948247 | AR7: https://market.yandex.ru/card/cat-support-dlya-kastrirovannykh-i-sterilizovannykh-kotov/103542519891?businessId=8291477&clid=8291477&model_id=44497703&distr_type=8&pp=605 | AW7: Витамины и добавки для животных | AX7: Витамины для кастрированных и стерилизованных котов, 100 таблеток | AY7: товары для животных / ветаптека / витамины для животных и птиц | BD7: Алексей | BE7: Кристина | BF7: Анна Пирогова | BG7: Екатерина Доможирова | BH7: Екатерина Доможирова | BI7: Екатерина Доможирова | BL7: 4605543011153 | BM7: 2309903100 | BN7: СТО 42310364-0042-2023 | BO7: https://drive.google.com/drive/folders/1EJ8QC9PqNnODOuu3qt12V3UPgRlQGVat | BP7: меркурий | BS7: лактоза; дрожжи пивные; фитокомплекс: листьев березы, створок фасоли, листьев подорожника большого, травы душицы, корней одуванчика, травы тысячелистника, цветков ноготков, травы зверобоя, цветков лабазника вязолистного, листьев мяты перечной, цветков ромашки; минеральный комплекс; мука рыбная; крахмал; стеарат кальция; L-карнитин; ПВП; таурин; сера; масло рыжиковое; краситель пищевой. | BU7: корм дают ежедневно по 1 г (2 шт.) 2 раза в день | BW7: при температуре от 0 до 25 oС | BX7: 100 | BY7: Таблетки | CA7: 18 месяцев | CB7: 18 месяцев | CC7: https://docs.google.com/document/d/1RTioq-2_e3hK5brYg7srNivrKihOx92EEEbnue87y00/edit?tab=t.0 | CF7: https://drive.google.com/drive/u/0/folders/1g_p7fO6i6NuPWi4GRMAvunnDvxfLGqJC | CM7: =IFERROR(VLOOKUP(B7,CC!A:D,4,0)," ") -> 53.65 | CN7: ООО "ВЕДА" | CP7: Дмитрий Алексеев / Dmitry Alekseev Коммерческий директор ООО "ВЕДА Вет-Фарм" / Commercial Director VEDA Vet-Farm +7-919-766-6452 dmitriy.alexeev@vedaved.ru | CQ7: 30 | CS7: 1 | CT7: нет | CY7: FALSE | CZ7: FALSE | DA7: FALSE | DB7: FALSE | DG7: Термо | DJ7: 4 | DK7: 8 | DL7: 4 | DM7: 128 | DN7: 0.06
A8: Биг-Л | B8: Harly_cat_teeth_bones_100tabs | C8: Harly | D8: Актуальный | E8: кд | F8: Витамины для костей для кошек, Harly, 100 таблеток | G8: Корма и Кормовые добавки | H8: Витамины для кошек | K8: TRUE | L8: TRUE | M8: TRUE | N8: TRUE | O8: FALSE | P8: FALSE | Q8: FALSE | S8: HB101100401 | T8: Harly_cat_teeth_bones_100tabs | U8: Harly_cat_teeth_bones_100tabs | V8: Harly_cat_teeth_bones_100tabs | AA8: 163688556 | AB8: 1018532111 | AC8: 102625995832 | AH8: Витамины для костей для кошек, Harly, 100 таблеток | AI8: Витамины для кошек для костей и зубов | AJ8: Витамины для кошек для костей и зубов, 100 таблеток | AK8: Витамины для кошек для костей и зубов, комплекс витаминов для кошек 100 таблеток | AP8: https://www.wildberries.ru/catalog/163688556/detail.aspx | AQ8: https://www.ozon.ru/product/1018532111 | AR8: https://market.yandex.ru/card/teeth--bones-funktsionalnyy-korm-dlya-zubov-i-kostey-dlya-koshek/103614081635?businessId=8291477&clid=8291477&model_id=44500665&distr_type=8&pp=605 | AW8: Витамины и добавки для животных | AX8: Витамины для кошек для костей и зубов, 100 таблеток | AY8: товары для животных / ветаптека / витамины для животных и птиц | BD8: Алексей | BE8: Кристина | BF8: Анна Пирогова | BG8: Екатерина Доможирова | BH8: Екатерина Доможирова | BI8: Екатерина Доможирова | BL8: 4605543011160 | BM8: 2309903100 | BN8: СТО 42310364-0043-2023 | BO8: https://drive.google.com/drive/folders/1mpyXfn29J6FjP1QVEKQT3NjykIDvNJyV | BP8: меркурий | BS8: дрожжи пивные, лактоза; крахмал; фитокомплекс: корневищ аира, травы хвоща полевого, цветков лабазника вязолистного, травы фиалки, листьев березы, листьев шалфея, корней лопуха, почек березовых, цветков ноготков, листьев мяты перечной, почек сосны; природный минеральный комплекс; паровая мука рыбная; гидролизат коллагена; L-карнитин; таурин; сера; стеарат кальция. | BU8: котятам по 0,5г - 1 г (1-2 шт) 2 раза в день; кошкам старше 8 месяцев по 1-1,5 г (2-3 шт) раза в день; длястареющим животных по 1 г (1) 2 раза в день | BW8: при температуре от 0 до 25 oС | BX8: 100 | BY8: Таблетки | CA8: 18 месяцев | CB8: 18 месяцев | CC8: https://docs.google.com/document/d/1nRMqrHOUL-HxNDtP1kKkagtZQlN6WmJEcH715UB0ctc/edit?tab=t.0 | CF8: https://drive.google.com/drive/u/0/folders/1g_p7fO6i6NuPWi4GRMAvunnDvxfLGqJC | CM8: =IFERROR(VLOOKUP(B8,CC!A:D,4,0)," ") -> 53.65 | CN8: ООО "ВЕДА" | CP8: Дмитрий Алексеев / Dmitry Alekseev Коммерческий директор ООО "ВЕДА Вет-Фарм" / Commercial Director VEDA Vet-Farm +7-919-766-6452 dmitriy.alexeev@vedaved.ru | CQ8: 30 | CS8: 1 | CT8: нет | CY8: FALSE | CZ8: FALSE | DA8: FALSE | DB8: FALSE | DG8: и тд | DJ8: 4 | DK8: 8 | DL8: 4 | DM8: 128 | DN8: 0.06
A9: Биг-Л | B9: harly_paste_75ml | C9: Harly | D9: Вывод | E9: Перезавели v2 | F9: Паста для вывода шерсти кошек ,Harly, 75 мл | G9: Корма и Кормовые добавки | H9: Витамины для кошек | K9: TRUE | L9: TRUE | M9: TRUE | N9: TRUE | O9: FALSE | P9: FALSE | Q9: FALSE | S9: HB101100408 | T9: harly_paste_75ml | U9: harly_paste_75ml | V9: harly_paste_75ml | AA9: 265523439 | AB9: 1711363073 | AC9: 103597697138 | AH9: Паста для вывода шерсти кошек ,Harly, 75 мл | AI9: Паста для вывода шерсти кошек и хорьков 75 мл | AJ9: Паста для вывода шерсти кошек и хорьков Harly 75 мл | AK9: Паста для вывода шерсти кошек и хорьков, мальт-паста для животных Harly 75 мл | AP9: https://www.wildberries.ru/catalog/265523439/detail.aspx | AQ9: https://www.ozon.ru/product/1711363073 | AR9: https://market.yandex.ru/card/harly-pasta-dlya-vyvedeniya-shersti/103614089888?businessId=8291477&clid=8291477&model_id=824211224&distr_type=8&pp=605 | AW9: Пасты для животных | AX9: Паста для вывода шерсти кошек и хорьков Harly 75 мл | AY9: товары для животных / ветаптека / витамины для животных и птиц | BD9: Выведено | BE9: Кристина | BF9: Анна Пирогова | BG9: Екатерина Доможирова | BH9: Екатерина Доможирова | BI9: Екатерина Доможирова | BL9: 4605543013096 | BM9: 2309909609 | BN9: ДС | BP9: меркурий, ЧЗ | BS9: Состав : масло растительное пищевое, гидролизат белковый, жир растительный, стабилизатор, экстракт солода, масло клещевины, волокна растительные пищевые, масло вазелиновое, лецитин соевый, экстракт кошачьей мяты, антиоксидант, консервант. | BU9: давать один раз в день до кормления или добавлять в корм: кошкам массой более 2 кг - 5 см пасты; кошкам массой до 2 кг, котятам, хорькам - 2 см пасты. В период линьки порцию можно увеличить вдвое. | BW9: Хранить в течение 12 месяцев при температуре от 0 до 25 ℃. Вскрытую упаковку рекомендуется хранить в холодильнике. | BX9: 75 | BY9: мл | CA9: 12 месяцев | CB9: 12 месяцев | CC9: https://docs.google.com/document/d/1XPxvc0_rnwY-m_Fi8Z3tguz_Y9D15h6gupsd_lqR5Tk/edit | CM9: =IFERROR(VLOOKUP(B9,CC!A:D,4,0)," ") -> 102 | CN9: ООО "ВЕДА" | CP9: Дмитрий Алексеев / Dmitry Alekseev Коммерческий директор ООО "ВЕДА Вет-Фарм" / Commercial Director VEDA Vet-Farm +7-919-766-6452 dmitriy.alexeev@vedaved.ru | CQ9: 30 | CS9: 1 | CT9: нет | CY9: FALSE | CZ9: FALSE | DA9: FALSE | DB9: FALSE | DJ9: 5 | DK9: 15 | DL9: 5 | DM9: 375 | DN9: 0.092
A10: Биг-Л | B10: Harly_Skin_Coat | C10: Harly | D10: Актуальный | F10: Витамины для здоровой шерсти для собак, Harly, 100 таблеток | G10: Корма и Кормовые добавки | H10: Витамины для собак | K10: TRUE | L10: TRUE | M10: TRUE | N10: TRUE | O10: FALSE | P10: FALSE | Q10: FALSE | S10: HB101100402 | T10: Harly_Skin_Coat | U10: Harly_Skin_Coat | V10: Harly_Skin_Coat | AA10: 150253274 | AB10: 884560852 | AC10: 102626212762 | AH10: Витамины для здоровой шерсти для собак, Harly, 100 таблеток | AI10: Витамины для собак и щенков для здоровой и красивой шерсти | AJ10: Витамины для собак и щенков для здоровой и красивой шерсти, 100 таблеток | AK10: Витамины для собак и щенков для здоровой и красивой шерсти, 100 таблеток | AP10: https://www.wildberries.ru/catalog/150253274/detail.aspx | AQ10: https://www.ozon.ru/product/884560852 | AR10: https://market.yandex.ru/card/skin--coat-funktsionalnyy-korm-dlya-sobak-dlya-shersti/103614081637?businessId=8291477&clid=8291477&model_id=44886188&distr_type=8&pp=605 | AW10: Витамины и добавки для животных | AX10: Витамины для собак и щенков для здоровой и красивой шерсти, 100 таблеток | AY10: товары для животных / ветаптека / витамины для животных и птиц | BD10: Алексей | BE10: Кристина | BF10: Анна Пирогова | BG10: Екатерина Доможирова | BH10: Екатерина Доможирова | BI10: Екатерина Доможирова | BL10: 4605543011092 | BM10: 2309903100 | BN10: СТО 42310364-0061-2022 | BO10: https://drive.google.com/drive/folders/1MFf-7yPFgLdMXDrXjcxVgFiVJH8U2vuD | BP10: меркурий | BS10: корней лопуха, листьев крапивы, листьев березы, цветков ромашки, травы чабреца, корневищ аира, травы череды, корней солодки, травы подмаренника, листьев подорожника, травы тысячелистника; минеральный комплекс; дрожжи пивные; L-карнитин; гидролизат коллагена; сера; вспомогательные компоненты. | BU10: щенкам и собакам мелких пород (10 кг) по 0,5г(1шт) 2 раза в день;собакам средних размеров (до 30 кг) по 1-1,5 г (2-3 шт) раза в день;собакам крупных размеров (свыше 30 кг) по 2,5 (5 шт) 2 раза в день | BW10: при температуре от 0 до 25 oС | BX10: 100 | BY10: таблеток | CA10: 18 месяцев | CB10: 18 месяцев | CC10: https://docs.google.com/document/d/1UikjX911kCO0UpzSvjsVdQLtyppRaN72OG_7o70i1iQ/edit?tab=t.0 | CF10: https://drive.google.com/drive/u/0/folders/1g_p7fO6i6NuPWi4GRMAvunnDvxfLGqJC | CM10: =IFERROR(VLOOKUP(B10,CC!A:D,4,0)," ") -> 53.4 | CN10: ООО "ВЕДА" | CP10: Дмитрий Алексеев / Dmitry Alekseev Коммерческий директор ООО "ВЕДА Вет-Фарм" / Commercial Director VEDA Vet-Farm +7-919-766-6452 dmitriy.alexeev@vedaved.ru | CQ10: 30 | CS10: 1 | CT10: нет | CY10: FALSE | CZ10: FALSE | DA10: FALSE | DB10: FALSE | DJ10: 4 | DK10: 8 | DL10: 4 | DM10: 128 | DN10: 0.06
A11: Биг-Л | B11: harly_dog_antiallergy_100tabs | C11: Harly | D11: Актуальный | F11: Витамины противоаллергические собакам, Harly, 100 таблеток | G11: Корма и Кормовые добавки | H11: Витамины для собак | K11: TRUE | L11: TRUE | M11: TRUE | N11: TRUE | O11: FALSE | P11: FALSE | Q11: FALSE | S11: HB101100405 | T11: harly_dog_antiallergy_100tabs | U11: harly_dog_antiallergy_100tabs | V11: harly_dog_antiallergy_100tabs | AA11: 232468472 | AB11: 1581829359 | AC11: 103527751380 | AH11: Витамины противоаллергические собакам, Harly, 100 таблеток | AI11: Витамины противоаллергические собакам | AJ11: Витамины противоаллергические собакам Harly Dog Anti-Allergy 100 таблеток | AK11: Витамины противоаллергические для собак Harly Dog Anti-Allergy 100 таблеток | AP11: https://www.wildberries.ru/catalog/232468472/detail.aspx | AQ11: https://www.ozon.ru/product/1581829359 | AR11: https://market.yandex.ru/card/anti-allergy-dlya-sobak--1/103542523691?businessId=8291477&clid=8291477&model_id=679202716&distr_type=8&pp=605 | AW11: Витамины и добавки для животных | AX11: Витамины противоаллергические собакам Harly Dog Anti-Allergy 100 таблеток | AY11: товары для животных / ветаптека / витамины для животных и птиц / витамины для животных и птиц | BD11: Алексей | BE11: Кристина | BF11: Анна Пирогова | BG11: Екатерина Доможирова | BH11: Екатерина Доможирова | BI11: Екатерина Доможирова | BL11: 4605543012471 | BM11: 2309903100 | BN11: N РОСС RU Д-RU.PA01.B.15564/24 от 16.04.2024 до 14.04.2027 | BO11: https://drive.google.com/drive/folders/1o1P40yl_7ZR8-xRy4wZf7EhJzyXZkr3- | BP11: меркурий | BS11: лактоза; дрожжи пищевые пивные сухие; фитокомплекс: травы сушеницы топяной, травы череды, травы тысячелистника, травы чистотела, почек березовых, листьев березы, листьев подорожника большого, корней лопуха, корней одуванчика, цветков ноготков; минеральный комплекс (кальция фосфат дефторированный); крахмал; стеарат кальция; L-карнитин; ПВП; сера кормовая; вкусо-ароматическая пищевая добавка «Бекон». | BU11: Рекомендации по кормлению: щенкам и собакам мелких пород (до 10 кг) по 0,5 г (1 шт.) 2 раза в день; собакам средних размеров (до 30 кг) по 1 – 1,5 г (2-3 шт.) 2 раза в день; собакам крупных размеров (свыше 30 кг) по 2,5 г (5 шт.) 2 раза в день. | BW11: при температуре от 0 до 25 oС | BX11: 100 | BY11: таблеток | CA11: 18 месяцев | CB11: 18 месяцев | CC11: https://docs.google.com/document/d/1Fy9Ve-kCbeluAI0L32QSpa4uGjqvZAu9KV47IS7glV4/edit | CM11: =IFERROR(VLOOKUP(B11,CC!A:D,4,0)," ") -> 53.75 | CN11: ООО "ВЕДА" | CP11: Дмитрий Алексеев / Dmitry Alekseev Коммерческий директор ООО "ВЕДА Вет-Фарм" / Commercial Director VEDA Vet-Farm +7-919-766-6452 dmitriy.alexeev@vedaved.ru | CQ11: 30 | CS11: 1 | CT11: нет | CY11: FALSE | CZ11: FALSE | DA11: FALSE | DB11: FALSE | DJ11: 4 | DK11: 8 | DL11: 4 | DM11: 128 | DN11: 0.06
A12: Биг-Л | B12: Harly_Joint_Care | C12: Harly | D12: Актуальный | F12: Витамины для костей суставов для собак, Harly, 100 таблеток | G12: Корма и Кормовые добавки | H12: Витамины для собак | K12: TRUE | L12: TRUE | M12: TRUE | N12: TRUE | O12: FALSE | P12: FALSE | Q12: FALSE | S12: HB101100403 | T12: Harly_Joint_Care | U12: Harly_Joint_Care | V12: Harly_Joint_Care | AA12: 150262548 | AB12: 884578393 | AC12: 102626212766 | AH12: Витамины для костей суставов для собак, Harly, 100 таблеток | AI12: Витамины для собак и щенков для костей суставов и связок | AJ12: Витамины для собак и щенков для костей суставов и связок 100 таблеток | AK12: Витамины для собак и щенков для костей суставов и связок 100 таблеток | AP12: https://www.wildberries.ru/catalog/150262548/detail.aspx | AQ12: https://www.ozon.ru/product/884578393 | AR12: https://market.yandex.ru/card/joint-care-funktsionalnyy-korm-dlya-sobak-dlya-sustavov/103542518194?businessId=8291477&clid=8291477&model_id=44500663&distr_type=8&pp=605 | AW12: Витамины и добавки для животных | AX12: Витамины для собак и щенков для костей суставов и связок 100 таблеток | AY12: товары для животных / ветаптека / витамины для животных и птиц | BD12: Алексей | BE12: Кристина | BF12: Анна Пирогова | BG12: Екатерина Доможирова | BH12: Екатерина Доможирова | BI12: Екатерина Доможирова | BL12: 4605543011085 | BM12: 2309903100 | BN12: СТО 42310364-0060-2022 | BO12: https://drive.google.com/drive/folders/1IQ51gbZJ8MzYP29NXeoOOScaQ0jQZK3C | BP12: меркурий | BS12: коры дуба, листьев эвкалипта, корней окопника, корневищ аира, травы фиалки, листьев березы, корней одуванчика, травы зверобоя, побегов багульника, цветков лабазника вязолистного; дрожжи пивные; гидролизат коллагена; L-карнитин; сера; витамин D3; вспомогательные компоненты. | BU12: корм дают ежедневно по 1 г (2 шт.) 2 раза в день | BW12: при температуре от 0 до 25 oС | BX12: 100 | BY12: таблеток | CA12: 18 месяцев | CB12: 18 месяцев | CC12: https://docs.google.com/document/d/1P2KK6r50RbQvRpU3E3b6nd7ld16cP7H7MoVk9M_1Ums/edit?tab=t.0 | CF12: https://drive.google.com/drive/u/0/folders/1g_p7fO6i6NuPWi4GRMAvunnDvxfLGqJC | CM12: =IFERROR(VLOOKUP(B12,CC!A:D,4,0)," ") -> 53.4 | CN12: ООО "ВЕДА" | CP12: Дмитрий Алексеев / Dmitry Alekseev Коммерческий директор ООО "ВЕДА Вет-Фарм" / Commercial Director VEDA Vet-Farm +7-919-766-6452 dmitriy.alexeev@vedaved.ru | CQ12: 30 | CS12: 1 | CT12: нет | CY12: FALSE | CZ12: FALSE | DA12: FALSE | DB12: FALSE | DJ12: 8 | DK12: 4 | DL12: 8 | DM12: 256 | DN12: 0.063
A13: Биг-Л | B13: harly_sardineoil_250ml | C13: Harly | D13: Новинка | F13: Harly масло сардины 250 мл | G13: Корма и Кормовые добавки | H13: Витамины для собак | K13: FALSE | L13: TRUE | M13: TRUE | N13: FALSE | O13: FALSE | P13: FALSE | Q13: FALSE | T13: harly_sardineoil_250ml | U13: harly_sardineoil_250ml | V13: harly_sardineoil_250ml | AA13: 786916846 | AB13: 3463925696 | AC13: 5077651579 | BE13: Семен | BL13: 4620290621547 | BM13: 2309109000 | BO13: https://drive.google.com/drive/u/0/folders/1f6GGEzLVv8y1ay2J45GONVZoZVXjddLa | BP13: ЧЗ | BS13: 100% масло сардины | BU13: одно нажатие дозатора – 1,15 мл. Суточная норма: на каждые 5 кг веса питомца – 1,15 мл. | BW13: Хранить в прохладном, защищенном от света месте (в летний период не выше 30 С). Вскрытый флакон хранить в холодильнике при температуре от +4 С до +8 С. | BX13: 250 | BY13: мл | CA13: 12 месяцев | CC13: https://docs.google.com/document/d/1BKKy3Blk0MIwdeRBkS6P1iBdo8cf4Nqv_AtheYEpn50/edit?tab=t.0 | CM13: =IFERROR(VLOOKUP(B13,CC!A:D,4,0)," ") | CN13: ООО Терра-пласт | CP13: Гордиенко Евгения Степановна (812)748-22-25(доб.101) +7(962)689-06-49 stm@gkfavorite.ru | CQ13: 30 | CY13: FALSE | CZ13: FALSE | DA13: FALSE | DB13: FALSE
A14: Биг-Л | B14: Harly_dog_teeth_bones_100tabs | C14: Harly | D14: Актуальный | F14: Витамины для костей для собак, ,Harly, 100 таблеток | G14: Корма и Кормовые добавки | H14: Витамины для собак | K14: TRUE | L14: TRUE | M14: TRUE | N14: TRUE | O14: FALSE | P14: FALSE | Q14: FALSE | S14: HB101100404 | T14: Harly_dog_teeth_bones_100tabs | U14: Harly_dog_teeth_bones_100tabs | V14: Harly_dog_teeth_bones_100tabs | AA14: 163687757 | AB14: 1018530861 | AC14: 102621828617 | AH14: Витамины для костей для собак, ,Harly, 100 таблеток | AI14: Витамины для собак и щенков для костей и зубов | AJ14: Витамины для собак и щенков для костей и зубов, 100 таблеток | AK14: Витамины для собак и щенков для костей и зубов, 100 таблеток | AP14: https://www.wildberries.ru/catalog/163687757/detail.aspx | AQ14: https://www.ozon.ru/product/1018530861 | AR14: https://market.yandex.ru/card/teeth--bones-funktsionalnyy-korm-dlya-zubov-i-kostey-dlya-sobak/103614081636?businessId=8291477&clid=8291477&model_id=44502679&distr_type=8&pp=605 | AW14: Витамины и добавки для животных | AX14: Витамины для собак и щенков для костей и зубов, 100 таблеток | AY14: товары для животных / ветаптека / витамины для животных и птиц | BD14: Алексей | BE14: Кристина | BF14: Анна Пирогова | BG14: Екатерина Доможирова | BH14: Екатерина Доможирова | BI14: Екатерина Доможирова | BL14: 4605543011177 | BM14: 2309903100 | BN14: СТО 42310364-0044-2023 | BO14: https://drive.google.com/drive/folders/1p5gWqcP76Vsv2Evi4DwpeTeky0kE3iyV | BP14: меркурий | BS14: лактоза; дрожжи пивные; фитокомплекс: корневищ аира, травы хвоща полевого, цветков лабазника вязолистного, травы фиалки, листьев березы, листьев шалфея, корней лопуха, почек березовых, цветков ноготков, листьев мяты перечной, почек сосны; минеральный комплекс; крахмал; стеарат кальция; L-карнитин; ПВП; гидролизат коллагена; ароматическая пищевая добавка; сера. | BU14: щенкам и собакам мелких пород (10 кг) по 0,5г(1шт) 2 раза в день;собакам средних размеров (до 30 кг) по 1-1,5 г (2-3 шт) раза в день;собакам крупных размеров (свыше 30 кг) по 2,5 (5 шт) 2 раза в день | BW14: при температуре от 0 до 25 oС | BX14: 100 | BY14: таблеток | CA14: 18 месяцев | CB14: 18 месяцев | CC14: https://docs.google.com/document/d/1GIhxI6rjxcKWcXkVQWFOUMR8k_q55sJ6ghopBpX2UKc/edit?tab=t.0 | CF14: https://drive.google.com/drive/u/0/folders/1g_p7fO6i6NuPWi4GRMAvunnDvxfLGqJC | CM14: =IFERROR(VLOOKUP(B14,CC!A:D,4,0)," ") -> 53.4 | CN14: ООО "ВЕДА" | CP14: Дмитрий Алексеев / Dmitry Alekseev Коммерческий директор ООО "ВЕДА Вет-Фарм" / Commercial Director VEDA Vet-Farm +7-919-766-6452 dmitriy.alexeev@vedaved.ru | CQ14: 30 | CS14: 1 | CT14: нет | CY14: FALSE | CZ14: FALSE | DA14: FALSE | DB14: FALSE | DJ14: 4 | DK14: 8 | DL14: 4 | DM14: 128 | DN14: 0.06
A15: Биг-Л | B15: Harly_dogcat_probiotics_20tabs | C15: Harly | D15: Актуальный | F15: Пребиотик для собак и кошек ,Harly, 20 таб | G15: Корма и Кормовые добавки | H15: Витамины общие | K15: TRUE | L15: TRUE | M15: TRUE | N15: TRUE | O15: FALSE | P15: FALSE | Q15: FALSE | S15: HB101100409 | T15: Harly_dogcat_probiotics_20tabs | U15: Harly_dogcat_probiotics_20tabs | V15: Harly_dogcat_probiotics_20tabs | AA15: 232465954 | AB15: 1581825452 | AC15: 103510407614 | AH15: Пребиотик для собак и кошек ,Harly, 20 таб | AI15: Пробиотик для собак и кошек лактобактерии для профилактики | AJ15: Пребиотик для собак и кошек лактобактерии для профилактики жкт | AK15: Пробиотик для собак и кошек лактобактерии для профилактики жкт, витамины для животных 20 шт. в упаковке | AP15: https://www.wildberries.ru/catalog/232465954/detail.aspx | AQ15: https://www.ozon.ru/product/1581825452 | AR15: https://market.yandex.ru/card/dog-and-cat-probiotics--1/103542563878?businessId=8291477&clid=8291477&model_id=616053073&distr_type=8&pp=605 | AW15: Витамины и добавки для животных | AX15: Пребиотик для собак и кошек лактобактерии для профилактики жкт | AY15: товары для животных / ветаптека / ветеринарные препараты | BD15: Алексей | BE15: Семен | BF15: Анна Пирогова | BG15: Екатерина Доможирова | BH15: Екатерина Доможирова | BI15: Екатерина Доможирова | BL15: 4605543012495 | BM15: 2309903100 | BN15: N РОСС RU Д-RU.PA01.B.15696/24 от 16.04.2024 до 15.04.2027 | BO15: https://drive.google.com/drive/folders/1L065BxHDMUdVQxodAmNqzK24QFsduBfI | BP15: меркурий | BS15: комплекс лиофильно высушенных культур пробиотических бактерий - бифидобактерий, лактобактерий, стрептококков; вспомогательные компоненты: лактоза, крахмал, стеарат кальция. | BU15: Рекомендации по кормлению: функциональный корм дают 2 раза в сутки из расчета: собакам - по 1 таблетке на каждые 10 кг массы; кошкам и собакам мелких пород - по 1 таблетке; щенкам мелких пород, котятам, хорькам и грызунам - по 1 таблетке. Можно растворять в воде для выпаивания или смешивать с небольшим количеством любимого корма. Продолжительность включения в рацион 5-10 дней. Ограничений для применения и несовместимости с различными рационами и кормами не выявлено. | BW15: Хранить в течение 12 месяцев при температуре от 0 до 10 ºС. Допускается хранение не более 10 суток при температуре до 25 ºС. | BX15: 20 | BY15: таблеток | CA15: 1 год | CB15: 12 месяцев | CC15: https://docs.google.com/document/d/16CMvYUaTc8W6xLuW6xuJqCabd0q3Dqms08x9tXcTvjI/edit | CM15: =IFERROR(VLOOKUP(B15,CC!A:D,4,0)," ") -> 51.86 | CN15: ООО "ВЕДА" | CP15: Дмитрий Алексеев / Dmitry Alekseev Коммерческий директор ООО "ВЕДА Вет-Фарм" / Commercial Director VEDA Vet-Farm +7-919-766-6452 dmitriy.alexeev@vedaved.ru | CQ15: 30 | CS15: 1 | CT15: нет | CY15: FALSE | CZ15: FALSE | DA15: FALSE | DB15: FALSE | DJ15: 5 | DK15: 8 | DL15: 5 | DM15: 200 | DN15: 0.018
A16: Биг-Л | B16: qeep_perfect_spray_200ml | C16: qeep | D16: Актуальный | E16: Внимание, Цена ВБ | F16: Спрей солевой для объема волос, ,qeep, 200 мл | G16: Косметика | H16: Волосы | K16: TRUE | L16: TRUE | M16: TRUE | N16: TRUE | O16: TRUE | P16: FALSE | Q16: TRUE | S16: QC101100405 | T16: qeep_perfect_spray_200ml | U16: qeep_perfect_spray_200ml | V16: qeep_perfect_spray_200ml | W16: qeep_perfect_spray_200ml | Y16: qeep_perfect_spray_200ml | AA16: 377788941 | AB16: 2018960887 | AC16: 4315768672 | AD16: 99000115784 | AF16: QEEP-SOLEVSP | AH16: Спрей солевой для объема волос, ,qeep, 200 мл | AI16: Спрей для объема и укладки волос с фиксацией | AJ16: Спрей для волос солевой для объема и укладки волос с фиксацией qeep 200 мл | AK16: Спрей для объема и укладки волос с фиксацией, прикорневой объем волос qeep, 200 мл | AL16: Спрей для волос солевой для объема и укладки волос с фиксацией, qeep, 200 мл | AN16: Спрей для волос солевой для объема и укладки волос с фиксацией qeep 200 мл | AP16: https://www.wildberries.ru/catalog/377788941/detail.aspx | AQ16: https://www.ozon.ru/product/2018960887 | AR16: https://market.yandex.ru/card/sprey-dlya-obyema-i-ukladki-volos-s-fiksatsiyey-qeep-200-ml/4315768672?businessId=8291477&clid=8291477&model_id=1103677448&distr_type=8&pp=605 | AU16: https://mm.ru/product/sprej-dlya-volos-5898539?skuId=13170083 | AW16: Спреи | AX16: Спрей для волос солевой для объема и укладки волос с фиксацией qeep 200 мл | AY16: товары для красоты / косметика, парфюмерия и уход / уход за волосами / для укладки / лаки и спреи | AZ16: Уход для волос | BB16: Спреи | BD16: Мария | BE16: Кристина | BF16: Анна Пирогова | BG16: Екатерина Доможирова | BH16: Екатерина Доможирова | BI16: Екатерина Доможирова | BL16: 4670020498420 | BM16: 3305900009 | BN16: ДС | BO16: https://drive.google.com/drive/folders/1tkb0VjzFG6nTETD90FvT27TX2vLzgDjy | BP16: без ЧЗ | BS16: Вода очищенная, поливинилпирролидон, соль морская, мочевина, carepol 99, натрия гидроокись, молочная кислота, парфюмерная композиция, ПЭГ-40 гидрогенезированное касторовое масло, гидролизат кератина, Д-пантенол, феноксиэтанол, этилгексилглицерин, экстракт розмарина, экстракт орхидеи, твин 20. | BU16: хорошо встряхнуть флакон перед применением. Распылить на волосы, распределить руками по длине. Придайте волосам нужную форму своими руками. Дать волосам высохнуть естественным путём или с помощью фена. Не смывать. При необходимости повторить. | BW16: хранят при температуре не ниже 5˚С и не выше 25˚ Не допускается хранить продукцию под непосредственным воздействием солнечного света и вблизи отопительных приборов. | BX16: 200 | BY16: мл | CA16: 24 месяца | CB16: 24 месяца | CC16: https://docs.google.com/document/d/1as7qSPL_FDh8Gb9PLz5CNARde-H9drK_5pJMeQf_GK8/edit?tab=t.0 | CM16: =IFERROR(VLOOKUP(B16,CC!A:D,4,0)," ") -> 99.5 | CN16: ООО ПКФ Две линии (Алтэя) | CP16: Мария Чуйкова +7 (3854) 30-30-87 https://productaltai.com/ www.dvelinii.com моб., WhatsApp 8-903-948-3450 Алтайский край, г. Бийск, ул.Социалистическая д.11, стр. 1 | CQ16: 90 | CS16: 5 | CT16: нет | CY16: FALSE | CZ16: FALSE | DA16: FALSE | DB16: FALSE | DJ16: 5 | DK16: 16 | DL16: 5 | DM16: 400 | DN16: 0.228
A17: Биг-Л | B17: qeep_dlyarostavolos_100ml | C17: qeep | D17: Актуальный | E17: Внимание, Цена ВБ | F17: Спрей для роста и от выпадения волос ,qeep, 100 мл | G17: Косметика | H17: Волосы | K17: TRUE | L17: TRUE | M17: TRUE | N17: TRUE | O17: TRUE | P17: TRUE | Q17: FALSE | S17: QC101100406 | T17: qeep_dlyarostavolos_100ml | U17: qeep_dlyarostavolos_100ml | V17: qeep_dlyarostavolos_100ml | W17: qeep_dlyarostavolos_100ml | X17: qeep_dlyarostavolos_100ml | AA17: 449423638 | AB17: 2354324278 | AC17: 4909516637 | AD17: 99000115954 | AE17: MPL494786 | AH17: Спрей для роста и от выпадения волос ,qeep, 100 мл | AI17: Спрей сыворотка для роста волос | AJ17: Спрей для волос, для роста и от выпадения волос qeep 100 мл | AK17: Спрей для роста и от выпадения волос, сыворотка для роста волос активатор qeep 100 мл | AL17: спрей для волос, для роста и от выпадения волос, qeep, 100 мл | AM17: Спрей для волос, для роста и от выпадения волос | AP17: https://www.wildberries.ru/catalog/449423638/detail.aspx | AQ17: https://www.ozon.ru/product/2354324278 | AR17: https://market.yandex.ru/card/sprey-dlya-rosta-i-ot-vypadeniya-volos-qeep-100-ml/4480600215?businessId=8291477&clid=8291477&model_id=4909516636&distr_type=8&pp=605 | AS17: https://goldapple.ru/catalogsearch/result?q=99000115954 | AT17: https://www.letu.ru/product/qeep-sprei-dlya-volos-dlya-rosta-i-ot-vypadeniya-volos/175700153 | AW17: Сыворотки | AX17: Спрей для волос, для роста и от выпадения волос qeep 100 мл | AY17: товары для красоты / косметика, парфюмерия и уход / уход за волосами / маски и сыворотки | AZ17: Уход для волос | BA17: Уход за волосами >> Уход за волосами >> Сыворотка для ухода за волосами | BD17: Мария | BE17: Кристина | BF17: Анна Пирогова | BG17: Екатерина Доможирова | BH17: Екатерина Доможирова | BI17: Екатерина Доможирова | BL17: 4603320465434 | BM17: 3305900009 | BN17: ЕАЭС N RU Д-RU.РА03.В.29743/25 от 10.04.2025 по 10.04.2030 | BO17: https://drive.google.com/drive/folders/1ejD8pLP3trBa83tKqhil3_9DZnl-zh1B | BP17: без ЧЗ | BS17: Aqua, Niacinamide, Hydroxyethyl Urea, Glycerin, Rosemary Extract, Acetyl Tetrapeptide-3, Capsicum Annuum Extract, D-Panthenol, Phenoxyethanol, PEG-40 Hydrogenated Castor Oil, Fragrance, Glycolic Acid, Oleanolic acid, 1,2-Hexanediol, Ethylhexylglycerin, Hexamethylindanopyran, Hexyl Cinnamal, Tetramethyl Acetyloctahydronaphthalenes, Pinene, D-Limonene | BU17: Встряхните флакон и равномерно распылить средство на сухую или влажную кожу головы, разделяя волосы на проборы. Провести легкий массаж. Средство не загрязняет кожу головы и не требует смывания. Рекомендуется для регулярного использования. | BW17: при температуре от 0 до 25 oС | BX17: 100 | BY17: мл | CA17: 36 месяцев | CB17: 36 месяцев | CC17: https://docs.google.com/document/d/12STKI-NMYfL1xbAqJUqIbh1TKTru8BF48TrgEiod520/edit?tab=t.0 | CG17: 46071 | CH17: https://disk.yandex.ru/d/uHOU2gc2rR089A | CM17: =IFERROR(VLOOKUP(B17,CC!A:D,4,0)," ") -> 135.47 | CN17: ООО «Марвел 420049, Республика Татарстан, г Казань, ул Павлюхина, д. 99б, помещ. 1027. | CO17: Эйвон Бьюти | CP17: 79196215060 Евгений | CQ17: 60 | CS17: 3 | CT17: нет | CY17: FALSE | CZ17: FALSE | DA17: FALSE | DB17: FALSE | DJ17: 9 | DK17: 13 | DL17: 9 | DM17: 1053 | DN17: 0.15
A18: Биг-Л | B18: qeep_hairspray_200ml | C18: qeep | D18: Актуальный | E18: Внимание, небольшой остаток держим | F18: Спрей термозащита для волос 17 в 1 ,qeep, 200 мл | G18: Косметика | H18: Волосы | K18: TRUE | L18: TRUE | M18: TRUE | N18: TRUE | O18: FALSE | P18: TRUE | Q18: FALSE | S18: QC101100407 | T18: qeep_hairspray_200ml | U18: qeep_hairspray_200ml | V18: qeep_hairspray_200ml | X18: qeep_hairspray_200ml | AA18: 268884161 | AB18: 1729383128 | AC18: 103578859652 | AE18: MPL405943 | AH18: Спрей термозащита для волос 17 в 1 ,qeep, 200 мл | AI18: Спрей для волос многофункциональный с кератином | AJ18: Спрей термозащита для волос 17 в 1 многофункциональный с кератином qeep 200 мл | AK18: Спрей для волос 17 в 1 многофункциональный с кератином qeep 200 мл | AM18: Спрей для волос 17 в 1 многофункциональный с кератином | AP18: https://www.wildberries.ru/catalog/268884161/detail.aspx | AQ18: https://www.ozon.ru/product/1729383128 | AR18: https://market.yandex.ru/card/sprey-dlya-volos-mnogofunktsionalnyy-s-keratinom-qeep-200-ml/103578859652?businessId=8291477&clid=8291477&model_id=1103677448&distr_type=8&pp=605 | AT18: https://www.letu.ru/product/qeep-sprei-dlya-volos-17-v-1-mnogofunktsionalnyi-s-keratinom/168000614?sort=default&open=ingredient&hide=expectedEffect | AW18: Спреи | AX18: Спрей термозащита для волос 17 в 1 многофункциональный с кератином qeep 200 мл | AY18: товары для красоты / косметика, парфюмерия и уход / уход за волосами / для укладки / лаки и спреи | BA18: Уход за волосами >> Уход за волосами >> Спрей для ухода за волосами | BD18: Мария | BE18: Кристина | BF18: Анна Пирогова | BG18: Екатерина Доможирова | BH18: Екатерина Доможирова | BI18: Екатерина Доможирова | BL18: 4670020498024 | BM18: 3305900009 | BN18: ДС | BO18: https://drive.google.com/drive/folders/1D9_9YHYClR7hdKWe5YPLWdcJy578H-4u | BP18: без ЧЗ | BS18: Aqua, Amodimethicone, Cetearyl Alcohol, Glycerin, Cetrimonium Chloride, Trideceth-12, Ceteareth 20, Polyquaternium-37, Behentrimonium Chloride, Lysine, Histidine, Arginine, Aspartic Acid, Threonine, Serine, Glutamic Acid, Proline, Glycine, Alanine, Valine, Methionine, Isoleucine, Leucine, Tyrosine, Phenylalanine, Cysteine, Sodium PCA, Glucose, Urea, Allantoin, Lactic Acid, Oenothera Biennis Oil, Retinyl Palmitate, Tocopheryl Acetate, Panthenol, Hydrolyzed Keratin, Hydrolysed Silk, Argania Spinosa Kernel Oil, PEG-7 Glyceryl Cocoate, Potassium Sorbate, Sodium Benzoate, Gluconolactone, Calcium Gluconate, PEG-40 Hydrogenated Castor Oil, Benzoic Acid, Dehydroacetic Acid, Parfum, Phenoxyethanol, Ethylhexylglycerin. | BU18: перед применением встряхните флакон. Нанесите средство на чистые и подсушенные волосы на расстоянии 10-20 см в необходимом количестве, распределите по длине волос. Приступите к укладке волос. | BW18: хранят при температуре не ниже 5˚С и не выше 25˚ Не допускается хранить продукцию под непосредственным воздействием солнечного света и вблизи отопительных приборов. | BX18: 200 | BY18: мл | CA18: 2 года | CB18: 24 месяца | CC18: https://docs.google.com/document/d/10J8C2tL_Ttlb0h2oWm5GtXjXdwtwyf_qKWKopwZQzFg/edit | CM18: =IFERROR(VLOOKUP(B18,CC!A:D,4,0)," ") -> 111.6 | CN18: ООО ПКФ Две линии (Алтэя) | CP18: Мария Чуйкова +7 (3854) 30-30-87 https://productaltai.com/ www.dvelinii.com моб., WhatsApp 8-903-948-3450 Алтайский край, г. Бийск, ул.Социалистическая д.11, стр. 1 | CQ18: 90 | CS18: 5 | CT18: нет | CY18: FALSE | CZ18: FALSE | DA18: FALSE | DB18: FALSE | DJ18: 4 | DK18: 18 | DL18: 4 | DM18: 288 | DN18: 0.23
A19: Биг-Л | B19: qeep_gummy_d3_60 | C19: qeep | D19: Под вопросом | E19: КЗ Внешка | F19: БАД Д3 мармеладки ,qeep, 60 штук | G19: БАДы | H19: Детские витамины | K19: TRUE | L19: TRUE | M19: TRUE | N19: TRUE | O19: TRUE | P19: FALSE | Q19: FALSE | S19: QB101100420 | T19: qeep_gummy_d3_60 | U19: qeep_gummy_d3_60 | V19: qeep_gummy_d3_60 | W19: qeep_gummy_d3_60 | AA19: 432821274 | AB19: 2214705163 | AC19: 4476305013 | AD19: 99000117740 | AH19: БАД Д3 мармеладки ,qeep, 60 штук | AI19: Витамин Д3 для детей жевательный | AJ19: Витамины для детей витамин Д3 жевательные мармеладки qeep 60 штук | AK19: Витамин Д3 для детей жевательный qeep 60 мармеладок, витамишки | AL19: витамины для детей витамин д3 жевательные мармеладки qeep со вкусом вишни 60 штук | AP19: https://www.wildberries.ru/catalog/432821274/detail.aspx | AQ19: https://www.ozon.ru/product/2214705163 | AR19: https://market.yandex.ru/card/vitamin-d3-dlya-detey-zhevatelnyy-qeep-60-marmeladok/4476305013?businessId=8291477&clid=8291477&model_id=1947049801&distr_type=8&pp=605 | AS19: https://goldapple.ru/catalogsearch/result?q=99000117740 | AW19: БАДы | AX19: Витамины для детей витамин Д3 жевательные мармеладки qeep 60 штук | AY19: аптека / витамины, минералы, добавки | AZ19: Бады витамины | BD19: Света | BE19: Семен | BF19: Анна Пирогова | BG19: Екатерина Доможирова | BH19: Екатерина Доможирова | BI19: Екатерина Доможирова | BL19: 4640332830317 | BM19: 2106909808 | BN19: AM.01.01.01.003.R.000594.08.23 от 17.08.2023 г. | BO19: https://drive.google.com/drive/folders/1jZ4eqgWNd8vmt2FebMgnvRLrkJrCvx9w | BP19: ЧЗ | BS19: патока, сахар, вода, желатин, носитель – глицерин, глазирователь (содержит глазирователи: воск карнаубский, воск пчелиный белый, антиокислитель – альфа-токоферол), регулятор кислотности – лимонная кислота, холекальциферол, жир молочный, ароматизатор натуральный «Вишня» | BU19: детям старше 3 лет и взрослым по 1 пастилке в день, разжевывая после еды. | BV19: индивидуальная непереносимость компонентов, беременность, кормление грудью, нарушения углеводного обмена (в том числе сахарный диабет). Перед применением рекомендуется проконсультироваться с врачом. Перед применением БАД детьми необходимо проконсультироваться с врачом-педиатром. Детям до 14 лет принимать БАД по согласованию и под наблюдением врача-педиатра. | BW19: в сухом, защищенном от воздействия прямых солнечных лучей и недоступном для детей месте при температуре не выше +25°С. | BX19: 60 | BY19: штук | CA19: 2 года | CB19: 24 месяца | CC19: https://docs.google.com/document/d/1IAHvVzgeKSqo1-9G60Q4yjs42ezg6WvRovlxkChGLZQ/edit?tab=t.0 | CM19: =IFERROR(VLOOKUP(B19,CC!A:D,4,0)," ") -> 220 | CN19: ООО ПК "Битра" | CP19: Михалева Галина тел. 495/988-93-50 доб.120 моб./whatsapp+7 916-905-60-40 Mikhalevabitra@yandex.ru | CQ19: 90 | CS19: 1 | CT19: нет | CY19: FALSE | CZ19: FALSE | DA19: FALSE | DB19: FALSE | DJ19: 7 | DK19: 13 | DL19: 7 | DM19: 637 | DN19: 0.235
A20: Биг-Л | B20: qeepomega_kids | C20: qeep | D20: Вывод | F20: БАД Омега 3 для детей 540 мг ,qeep, 90 капсул | G20: БАДы | H20: Детские витамины | K20: TRUE | L20: TRUE | M20: TRUE | N20: FALSE | O20: FALSE | P20: FALSE | Q20: FALSE | S20: QB101100475 | T20: qeepomega_kids | U20: qeepomega_kids | AA20: 138757897 | AB20: 809466646 | AH20: БАД Омега 3 для детей 540 мг ,qeep, 90 капсул | AI20: Омега 3 для детей с витамином Д и Е для иммунитета и роста | AJ20: Омега 3 витамины для детей 540 мг Qeep 90 капсул | AP20: https://www.wildberries.ru/catalog/138757897/detail.aspx | AQ20: https://www.ozon.ru/product/809466646 | AW20: БАДы | AX20: Омега 3 витамины для детей 540 мг Qeep 90 капсул | BD20: Света | BE20: Семен | BF20: Анна Пирогова | BG20: Екатерина Доможирова | BH20: Екатерина Доможирова | BI20: Екатерина Доможирова | BL20: 2253874668540 4620153900611 | BM20: 3504009000 | BN20: RU.77.99.11.003.R.003248.09.19 от 10.09.2019 г. | BO20: https://drive.google.com/drive/folders/1hjNWvHCJR_wfGIdgHTvU153navLEZsF2 | BP20: ЧЗ | BS20: рыбий жир, капсула желатиновая (желатин, глицерин, картофельный крахмал, фруктоза), кремния диоксид (носитель), натуральный ароматизатор «малина и травы», витамин Е (токоферола ацетат), ликопин (или бета-каротин) (краситель), антиокислитель «Гриндокс», витамин D3 (холекальциферол). | BU20: детям с 3х лет и взрослым по 1-2 капсулы 2 раза в день во время еды (разжевать). Продолжительность приема 1 месяц. При необходимости прием можно повторить в течение года. | BV20: индивидуальная непереносимость компонентов. Перед применением рекомендуется проконсультироваться с врачом, перед применением БАД детьми рекомендуется проконсультироваться с врачом-педиатром. | BW20: В недоступном для детей месте при температуре не выше 25°С. | BX20: 90 | BY20: таблеток | CA20: 2 года | CB20: 24 месяца | CF20: https://drive.google.com/drive/u/0/folders/10ZcNddpKKbQ2OW4wt_06WNYC5-1fTDJ1 | CM20: =IFERROR(VLOOKUP(B20,CC!A:D,4,0)," ") -> 336.44 | CN20: ООО «Сибфармконтракт», Россия, 634034, г. Томск, ул. Нахимова 8, стр. 11. | CS20: 10 | CT20: нет | CY20: FALSE | CZ20: FALSE | DA20: FALSE | DB20: FALSE | DJ20: 10 | DK20: 6 | DL20: 10 | DM20: 600 | DN20: 0.09
A21: Биг-Л | B21: qeep_gummy_magn_60 | C21: qeep | D21: Под вопросом | E21: Выяснить какой продукт | F21: БАД магний для детей мармеладки ,qeep, 60 штук | G21: БАДы | H21: Детский витамины | K21: TRUE | L21: TRUE | M21: TRUE | N21: TRUE | O21: TRUE | P21: FALSE | Q21: FALSE | S21: QB101100460 | T21: qeep_gummy_magn_60 | U21: qeep_gummy_magn_60 | V21: qeep_gummy_magn_60 | W21: qeep_gummy_magn_60 | AA21: 293062934 | AB21: 1773856028 | AC21: 103665495848 | AD21: 99000117794 | AH21: БАД магний для детей мармеладки ,qeep, 60 штук | AI21: Витамины для детей магний цитрат жевательные мармеладки | AJ21: Витамины для детей магний цитрат жевательные мармеладки qeep 60 штук | AK21: Витамины для детей магний цитрат жевательные мармеладки, мармеладные мишки qeep 60 штук | AL21: витамины для детей магний цитрат жевательные мармеладки qeep со вкусом ягодного микса 60 штук | AP21: https://www.wildberries.ru/catalog/293062934/detail.aspx | AQ21: https://www.ozon.ru/product/1773856028 | AR21: https://market.yandex.ru/card/vitaminy-dlya-detey-magniy-tsitrat-zhevatelnyye-marmeladki-qeep-60-shtuk/103665495848?businessId=8291477&clid=8291477&model_id=1947049801&distr_type=8&pp=605 | AS21: https://goldapple.ru/catalogsearch/result?q=99000117794 | AW21: БАДы | AX21: Витамины для детей магний цитрат жевательные мармеладки qeep 60 штук | AY21: аптека / витамины, минералы, добавки | AZ21: Бады витамины | BD21: Света | BE21: Семен | BF21: Анна Пирогова | BG21: Екатерина Доможирова | BH21: Екатерина Доможирова | BI21: Екатерина Доможирова | BL21: 4640346711336 | BM21: 2106909808 | BN21: AM.01.07.01.003.R.000302.03.24 от 11.03.2024 | BO21: https://drive.google.com/drive/folders/18RmLZdwskR-wJY5i0_FQQ25ZkllrDPc- | BP21: ЧЗ | BS21: магний цитрат, желатин, лимонная кислота - регулятор кислотности, натуральный ароматизатор "Ягодный микс", концентрат сока черной моркови – краситель, растительное масло (содержит карнаубский воск – глазирователь). глюкозный сироп, сахар. На предприятии используется сырье, содержащее продукты переработки молока, рыбы, ракообразных и сои. | BU21: детям старше 3-х лет и взрослым принимать по 1 пастилке в день во время еды. Не превышать рекомендуемую дозировку. | BV21: индивидуальная непереносимость компонентов, беременность, кормление грудью, нарушения углеводного обмена (в том числе сахарный диабет). Перед применением рекомендуется проконсультироваться с врачом. Перед применением БАД детьми необходимо проконсультироваться с врачом-педиатром. Детям до 14 лет принимать БАД по согласованию и под наблюдением врача-педиатра. | BW21: хранить в сухом, защищенном от попадания прямых солнечных лучей и недоступном для детей месте, при температуре от +5°С до +25°С и относительной влажности воздуха не более 75%. | BX21: 60 | BY21: шт | CA21: 18 месяцев | CB21: 18 месяцев | CC21: https://docs.google.com/document/d/1hFyhMnyjIC7Qb4t82VGmf3vdwfGg8itrcmm5MVkbmJM/edit?tab=t.0 | CM21: =IFERROR(VLOOKUP(B21,CC!A:D,4,0)," ") -> 228 | CN21: ООО "НУТРИЛЕНТ" | CP21: Анна Панкова @AnnaPankovaUKIZ | CQ21: 60 | CS21: 3 | CT21: нет | CY21: FALSE | CZ21: FALSE | DA21: FALSE | DB21: FALSE | DJ21: 11 | DK21: 5 | DL21: 11 | DM21: 605 | DN21: 0.165
A22: Биг-Л | B22: qeep_gummy_c_60 | C22: qeep | D22: Под вопросом | E22: КЗ Внешка | F22: БАД витамин С для детей мармеладки ,qeep, 60 штук | G22: БАДы | H22: Детский витамины | K22: TRUE | L22: TRUE | M22: TRUE | N22: TRUE | O22: TRUE | P22: FALSE | Q22: FALSE | S22: QB101100408 | T22: qeep_gummy_c_60 | U22: qeep_gummy_c_60 | V22: qeep_gummy_c_60 | W22: qeep_gummy_c_60 | AA22: 432841134 | AB22: 2214748873 | AC22: 4476310330 | AD22: 99000117739 | AH22: БАД витамин С для детей мармеладки ,qeep, 60 штук | AI22: Витамин С для детей жевательный | AJ22: Витамины для детей витамин с жевательные мармеладки qeep 60 штук | AK22: Витамин С для детей жевательный qeep 60 жевательных мармеладок, витамишки | AL22: витамины для детей витамин с жевательные мармеладки qeep со вкусом апельсина 60 штук | AP22: https://www.wildberries.ru/catalog/432841134/detail.aspx | AQ22: https://www.ozon.ru/product/2214748873 | AR22: https://market.yandex.ru/card/vitamin-s-dlya-detey-zhevatelnyy-qeep-60-zhevatelnykh-marmeladok/4476310330?businessId=8291477&clid=8291477&model_id=1947049801&distr_type=8&pp=605 | AS22: https://goldapple.ru/catalogsearch/result?q=99000117739 | AW22: БАДы | AX22: Витамины для детей витамин с жевательные мармеладки qeep 60 штук | AY22: аптека / витамины, минералы, добавки | AZ22: Бады витамины | BD22: Света | BE22: Семен | BF22: Анна Пирогова | BG22: Екатерина Доможирова | BH22: Екатерина Доможирова | BI22: Екатерина Доможирова | BL22: 4640332830300 | BM22: 2106909808 | BN22: AM.01.01.01.003.R.000584.08.23 от 15.08.2023 г. | BO22: https://drive.google.com/drive/folders/1-Pgr3i2_OqiWQSo8yCWIZcaUHTKtWguF | BP22: ЧЗ | BS22: патока, сахар, вода, желатин, носитель – глицерин, L-аскорбиновая кислота, глазирователь (содержит глазирователи: воск карнаубский и воск пчелиный белый, антиокислитель – альфа-токоферол), жир молочный; ароматизатор натуральный «Апельсин», краситель натуральный | BU22: детям старше 3 лет по 1 пастилке в день, взрослым по 1-2 пастилки в день, разжевывая после еды. | BV22: индивидуальная непереносимость компонентов, беременность, кормление грудью, нарушения углеводного обмена (в том числе сахарный диабет). Перед применением рекомендуется проконсультироваться с врачом. Перед применением БАД детьми необходимо проконсультироваться с врачом-педиатром. Детям до 14 лет принимать БАД по согласованию и под наблюдением врача-педиатра. | BW22: в сухом, защищенном от воздействия прямых солнечных лучей и недоступном для детей месте при температуре не выше +25°С. | BX22: 60 | BY22: штук | CA22: 2 года | CB22: 24 месяца | CC22: https://docs.google.com/document/d/1R65c50N_ld9jmDvK87XlIizSVB2GfnPinCtxjVCxlBU/edit?tab=t.0 | CM22: =IFERROR(VLOOKUP(B22,CC!A:D,4,0)," ") -> 220 | CN22: ООО ПК "Битра" | CP22: Михалева Галина тел. 495/988-93-50 доб.120 моб./whatsapp+7 916-905-60-40 Mikhalevabitra@yandex.ru | CQ22: 90 | CS22: 1 | CT22: нет | CY22: FALSE | CZ22: FALSE | DA22: FALSE | DB22: FALSE | DJ22: 7 | DK22: 13 | DL22: 7 | DM22: 637 | DN22: 0.227
A23: Биг-Л | B23: harly_pawsoap_500ml | C23: Harly | D23: Актуальный | F23: Мыло для лап собак ,Harly, 500 мл | G23: Косметика для животных | H23: Для лап | K23: TRUE | L23: TRUE | M23: TRUE | N23: TRUE | O23: FALSE | P23: FALSE | Q23: FALSE | S23: HC101100406 | T23: harly_pawsoap_500ml | U23: harly_pawsoap_500ml | V23: harly_pawsoap_500ml | AA23: 307874530 | AB23: 1828993605 | AC23: 103724222997 | AH23: Мыло для лап собак ,Harly, 500 мл | AI23: Мыло для лап собак с пантенолом и коллоидным серебром | AJ23: Мыло для лап собак с пантенолом и коллоидным серебром Harly 500 мл | AK23: Мыло для лап собак с пантенолом и коллоидным серебром Harly 500 мл | AP23: https://www.wildberries.ru/catalog/307874530/detail.aspx | AQ23: https://www.ozon.ru/product/1828993605 | AR23: https://market.yandex.ru/card/mylo-dlya-lap-sobak-s-pantenolom-i-kolloidnym-serebrom-harly-500-ml/103724222997?businessId=8291477&clid=8291477&model_id=944504526&distr_type=8&pp=605 | AW23: Мыло для животных | AX23: Мыло для лап собак с пантенолом и коллоидным серебром Harly 500 мл | AY23: товары для животных / косметика и гигиена / средства для уборки за животными | BD23: Алексей | BE23: Семен | BF23: Анна Пирогова | BG23: Екатерина Доможирова | BH23: Екатерина Доможирова | BI23: Екатерина Доможирова | BL23: 4673767781190 | BM23: 3307900008 | BN23: ДС | BO23: https://drive.google.com/drive/folders/1YcoxDfDh4ruJhBG56E2T7u94bh1w79DC | BP23: без ЧЗ | BS23: Water (Aqua), Sodium Laureth Sulfate, Cocamidopropyl Betaine, Glycerin, D-Panthenol, Cocamide DEA, Parfum, Citric Acid, Methylchloroisothiazolinone, Methylisothiazolinone, Colloidal Silver. | BU23: нанесите небольшое количество мыла на влажные руки, вспеньте, очистите образовавшейся пеной лапки питомца, смоченные водой. После тщательно смойте пену теплой водой. Рекомендуется после мытья обработать лапки воском для лап. Можно использовать для щенков от 6 месяцев. | BW23: при температуре от 0 до 25 oС | BX23: 500 | BY23: мл | CA23: 2 года | CB23: 24 месяца | CC23: https://docs.google.com/document/d/1_eSJtZO0eUrwiF0HDADKHQOq_usuoSpYtxP_JdmcIGk/edit?tab=t.0 | CG23: 46080 | CH23: https://disk.yandex.ru/d/Xz_B17SiYOGjpw | CM23: =IFERROR(VLOOKUP(B23,CC!A:D,4,0)," ") -> 92.75 | CN23: ООО "Батискаф" | CP23: Адель 8 962 557 2689 | CQ23: 45 | CS23: 3 | CT23: нет | CY23: FALSE | CZ23: FALSE | DA23: FALSE | DB23: FALSE | DJ23: 16 | DK23: 7 | DL23: 16 | DM23: 1792 | DN23: 0.551
A24: Биг-Л | B24: harly_pawprotector_30ml | C24: Harly | D24: Вывод | F24: Воск для лап ,Harly, 30 мл | G24: Косметика для животных | H24: Для лап | K24: TRUE | L24: TRUE | M24: TRUE | N24: FALSE | O24: FALSE | P24: FALSE | Q24: FALSE | S24: HC101100400 | T24: harly_pawprotector_30ml | U24: harly_pawprotector_30ml | AA24: 276247301 | AB24: 1745032627 | AH24: Воск для лап ,Harly, 30 мл | AI24: Воск для лап собак и кошек защитный | AJ24: Воск для лапок собак и кошек защитный Harly 30 мл | AP24: https://www.wildberries.ru/catalog/276247301/detail.aspx | AQ24: https://www.ozon.ru/product/1745032627 | AW24: Воск для лап | AX24: Воск для лапок собак и кошек защитный Harly 30 мл | BD24: Алексей | BE24: Семен | BF24: Анна Пирогова | BG24: Екатерина Доможирова | BH24: Екатерина Доможирова | BI24: Екатерина Доможирова | BL24: 4657786831579 | BN24: ДС | BP24: без ЧЗ | BS24: Масло семян гелиантуса однолетнего, Пчелиный воск, Вазелин, Пальмовое масло, Воск из отрубей риса (Oriza sativa), Коллоидное серебро, Ланолин, Микрокристаллический воск, гидрогенизированное растительное масло, гидрогенизированная пальмовая кислота, Стеарилстеарат, глицерилмоностеарат, Стеариновая кислота, Полисорбат 80, Олеат сорбитана, Ароматизатор, бутилгидрокситолуол. | BU24: нанесите средство на подушечки лап животных перед прогулкой, давая составу подсохнуть в течение минуты. После прогулки сотрите воск салфеткой и смойте остатки продукта теплой водой. | BW24: Температура хранения: от +5°C до +25°C. | BX24: 30 | BY24: мл | CA24: 1 год | CB24: 12 месяцев | CC24: https://docs.google.com/document/d/1KgCVfJkmpvVcN800fh2ozy8rpk8wfHp7o3jwNbMaPTk/edit?tab=t.0 | CM24: =IFERROR(VLOOKUP(B24,CC!A:D,4,0)," ") -> 181 | CN24: ООО «М9 Фарм» 445043, Самарская обл, Тольятти г, Южное шоссе, влд. 14 стр.3, помещение 31, 32. | CP24: Дмитрий +7 960 841 9108 | CQ24: 90 | CS24: 3 | CT24: нет | CY24: FALSE | CZ24: FALSE | DA24: FALSE | DB24: FALSE | DJ24: 3 | DK24: 7 | DL24: 3 | DM24: 63 | DN24: 0.071
A25: Биг-Л | B25: qeep_berberine_60caps | C25: qeep | D25: Актуальный | F25: БАД Берберин 500 мг ,qeep, 60 капсул | G25: БАДы | H25: Женские | K25: TRUE | L25: TRUE | M25: TRUE | N25: TRUE | O25: TRUE | P25: FALSE | Q25: FALSE | S25: QB101100405 | T25: qeep_berberine_60caps | U25: qeep_berberine_60caps | V25: qeep_berberine_60caps | W25: qeep_berberine_60caps | AA25: 198421782 | AB25: 1361997453 | AC25: 102650853073 | AD25: 99000118637 | AH25: БАД Берберин 500 мг ,qeep, 60 капсул | AI25: Берберин БАД для контроля сахара и жиросжигатель холестерина | AJ25: Берберин 500 мг Qeep 60 капсул | AK25: Берберин 500 мг капсулы для похудения и контроля аппетита Qeep 60 капсул | AL25: берберин 500 мг qeep 60 капсул | AP25: https://www.wildberries.ru/catalog/198421782/detail.aspx | AQ25: https://www.ozon.ru/product/1361997453 | AR25: https://market.yandex.ru/card/berberin-500-mg-qeep-60-kapsul/103374785698?businessId=8291477&clid=8291477&model_id=1826260757&distr_type=8&pp=605 | AS25: https://goldapple.ru/catalogsearch/result?q=99000118637 | AW25: БАДы | AX25: Берберин 500 мг Qeep 60 капсул | AY25: аптека / витамины, минералы, добавки | AZ25: Бады витамины | BD25: Света | BE25: Семен | BF25: Анна Пирогова | BG25: Екатерина Доможирова | BH25: Екатерина Доможирова | BI25: Екатерина Доможирова | BL25: 4630205148199 | BM25: 2106909808 | BN25: AM.01.01.01.003.R.000809.11.23 от 09.11.2023 | BO25: https://drive.google.com/drive/folders/1yXjmu5hDb-Pz71Rz8yc1YcRLpSpxr7Mh | BP25: ЧЗ | BS25: экстракт плодов барбариса, пиридоксин гидрохлорида (витамин В6), стеарат кальция, кремний диоксид коллоидный (АЭРОСИЛ@), твёрдая желатиновая капсула. | BU25: взрослым по 1 капсуле 1 раз в день. Продолжительность приёма: 1 месяц. При необходимости повторить. | BV25: индивидуальная непереносимость компонентов продукта, беременность, кормление грудью. Продукт не рекомендуется принимать детям до 18 лет. Перед применением проконсультироваться с врачом. | BW25: хранить в сухом, недоступном для детей месте, при температуре от +5 °С до +25 °С. | BX25: 60 | BY25: капсул | CA25: 2 года | CB25: 24 месяца | CC25: https://docs.google.com/document/d/1iR2ypw2bjgV0t5WgfvrEJygn4BKVz3hCoykhvJp9KKc/edit?usp=sharing | CM25: =IFERROR(VLOOKUP(B25,CC!A:D,4,0)," ") -> 293 | CN25: ООО «Жива Продукт ПРО». 350062, Россия, Краснодарский край, город Краснодар, улица Казбекская, дом 17, кв. (оф.) 85 | CP25: Магамадов Ибрагим e-mail: ima@dzivaproduct.ru сайт: www.dzivaproduct.ru сот.тел. +7-967-660-1277(доступен WhatsApp) | CQ25: 60 | CS25: 5 | CT25: да | CY25: FALSE | CZ25: FALSE | DA25: FALSE | DB25: FALSE | DJ25: 11 | DK25: 5 | DL25: 11 | DM25: 605 | DN25: 0.087
